2018-09-10 11:53:31,379 - flask.app - ERROR - 'DB' object has no attribute 'conn'
2018-09-10 12:17:27,285 - flask.app - ERROR - type object 'Error' has no attribute 'OperationalError'
2018-09-10 12:43:29,568 - werkzeug - WARNING -  * Debugger is active!
2018-09-10 12:43:29,579 - werkzeug - INFO -  * Debugger PIN: 947-245-363
2018-09-10 12:43:34,714 - werkzeug - INFO - 127.0.0.1 - - [10/Sep/2018 12:43:34] "GET /admin/view_changes/Podunk%3F186%3Fupdate HTTP/1.1" 500 -
2018-09-10 12:43:34,729 - werkzeug - INFO - 127.0.0.1 - - [10/Sep/2018 12:43:34] "GET /admin/view_changes/Podunk%3F186%3Fupdate?__debugger__=yes&cmd=resource&f=style.css HTTP/1.1" 200 -
2018-09-10 12:43:34,730 - werkzeug - INFO - 127.0.0.1 - - [10/Sep/2018 12:43:34] "GET /admin/view_changes/Podunk%3F186%3Fupdate?__debugger__=yes&cmd=resource&f=debugger.js HTTP/1.1" 200 -
2018-09-10 12:43:34,730 - werkzeug - INFO - 127.0.0.1 - - [10/Sep/2018 12:43:34] "GET /admin/view_changes/Podunk%3F186%3Fupdate?__debugger__=yes&cmd=resource&f=jquery.js HTTP/1.1" 200 -
2018-09-10 12:43:34,743 - werkzeug - INFO - 127.0.0.1 - - [10/Sep/2018 12:43:34] "GET /admin/view_changes/Podunk%3F186%3Fupdate?__debugger__=yes&cmd=resource&f=console.png HTTP/1.1" 200 -
2018-09-10 12:43:34,759 - werkzeug - INFO - 127.0.0.1 - - [10/Sep/2018 12:43:34] "GET /admin/view_changes/Podunk%3F186%3Fupdate?__debugger__=yes&cmd=resource&f=ubuntu.ttf HTTP/1.1" 200 -
2018-09-10 12:44:47,607 - werkzeug - INFO -  * Detected change in '/Users/hannahbako/Documents/VsCode/INCOSE_WWD/web/Routes.py', reloading
2018-09-10 12:52:30,476 - flask.app - ERROR - 'NoneType' object has no attribute 'logo'
2018-10-01 11:30:36,317 - werkzeug - INFO -  * Running on http://127.0.0.1:5000/ (Press CTRL+C to quit)
2018-10-01 11:30:36,319 - werkzeug - INFO -  * Restarting with stat
2018-10-01 11:30:36,559 - werkzeug - WARNING -  * Debugger is active!
2018-10-01 11:30:36,570 - werkzeug - INFO -  * Debugger PIN: 947-245-363
2018-10-01 11:31:12,043 - werkzeug - INFO -  * Detected change in '/Users/hannahbako/Documents/VsCode/INCOSE_WWD/web/Routes.py', reloading
2018-10-01 11:31:12,089 - werkzeug - INFO -  * Restarting with stat
2018-10-01 11:31:12,316 - werkzeug - WARNING -  * Debugger is active!
2018-10-01 11:31:12,325 - werkzeug - INFO -  * Debugger PIN: 947-245-363
2018-10-01 11:33:23,976 - werkzeug - INFO -  * Detected change in '/Users/hannahbako/Documents/VsCode/INCOSE_WWD/web/Routes.py', reloading
2018-10-01 11:33:24,014 - werkzeug - INFO -  * Restarting with stat
2018-10-16 20:39:24,924 - flask.app - ERROR - Exception on /all [GET]
Traceback (most recent call last):
  File "/usr/lib/python3.6/site-packages/mysql/connector/network.py", line 509, in open_connection
    self.sock.connect(sockaddr)
ConnectionRefusedError: [Errno 111] Connection refused

During handling of the above exception, another exception occurred:

Traceback (most recent call last):
  File "/home/centos/wwd/queries.py", line 450, in __init__
    self.conn = mysql.connector.connect(user='root', password='p@$sw0rD27', host='127.0.0.1', database='wwd')
  File "/usr/lib/python3.6/site-packages/mysql/connector/__init__.py", line 179, in connect
    return MySQLConnection(*args, **kwargs)
  File "/usr/lib/python3.6/site-packages/mysql/connector/connection.py", line 94, in __init__
    self.connect(**kwargs)
  File "/usr/lib/python3.6/site-packages/mysql/connector/abstracts.py", line 722, in connect
    self._open_connection()
  File "/usr/lib/python3.6/site-packages/mysql/connector/connection.py", line 207, in _open_connection
    self._socket.open_connection()
  File "/usr/lib/python3.6/site-packages/mysql/connector/network.py", line 512, in open_connection
    errno=2003, values=(self.get_address(), _strioerror(err)))
mysql.connector.errors.InterfaceError: 2003: Can't connect to MySQL server on '127.0.0.1:3306' (111 Connection refused)

During handling of the above exception, another exception occurred:

Traceback (most recent call last):
  File "/usr/lib/python3.6/site-packages/flask/app.py", line 2292, in wsgi_app
    response = self.full_dispatch_request()
  File "/usr/lib/python3.6/site-packages/flask/app.py", line 1815, in full_dispatch_request
    rv = self.handle_user_exception(e)
  File "/usr/lib/python3.6/site-packages/flask/app.py", line 1718, in handle_user_exception
    reraise(exc_type, exc_value, tb)
  File "/usr/lib/python3.6/site-packages/flask/_compat.py", line 35, in reraise
    raise value
  File "/usr/lib/python3.6/site-packages/flask/app.py", line 1813, in full_dispatch_request
    rv = self.dispatch_request()
  File "/usr/lib/python3.6/site-packages/flask/app.py", line 1799, in dispatch_request
    return self.view_functions[rule.endpoint](**req.view_args)
  File "Routes.py", line 104, in all_orgs
    db =DB()
  File "/home/centos/wwd/queries.py", line 453, in __init__
    except Error.OperationalError as e:
AttributeError: type object 'Error' has no attribute 'OperationalError'
2018-10-16 20:39:29,467 - flask.app - ERROR - Exception on /advanced_search [GET]
Traceback (most recent call last):
  File "/usr/lib/python3.6/site-packages/mysql/connector/network.py", line 509, in open_connection
    self.sock.connect(sockaddr)
ConnectionRefusedError: [Errno 111] Connection refused

During handling of the above exception, another exception occurred:

Traceback (most recent call last):
  File "/home/centos/wwd/queries.py", line 450, in __init__
    self.conn = mysql.connector.connect(user='root', password='p@$sw0rD27', host='127.0.0.1', database='wwd')
  File "/usr/lib/python3.6/site-packages/mysql/connector/__init__.py", line 179, in connect
    return MySQLConnection(*args, **kwargs)
  File "/usr/lib/python3.6/site-packages/mysql/connector/connection.py", line 94, in __init__
    self.connect(**kwargs)
  File "/usr/lib/python3.6/site-packages/mysql/connector/abstracts.py", line 722, in connect
    self._open_connection()
  File "/usr/lib/python3.6/site-packages/mysql/connector/connection.py", line 207, in _open_connection
    self._socket.open_connection()
  File "/usr/lib/python3.6/site-packages/mysql/connector/network.py", line 512, in open_connection
    errno=2003, values=(self.get_address(), _strioerror(err)))
mysql.connector.errors.InterfaceError: 2003: Can't connect to MySQL server on '127.0.0.1:3306' (111 Connection refused)

During handling of the above exception, another exception occurred:

Traceback (most recent call last):
  File "/usr/lib/python3.6/site-packages/flask/app.py", line 2292, in wsgi_app
    response = self.full_dispatch_request()
  File "/usr/lib/python3.6/site-packages/flask/app.py", line 1815, in full_dispatch_request
    rv = self.handle_user_exception(e)
  File "/usr/lib/python3.6/site-packages/flask/app.py", line 1718, in handle_user_exception
    reraise(exc_type, exc_value, tb)
  File "/usr/lib/python3.6/site-packages/flask/_compat.py", line 35, in reraise
    raise value
  File "/usr/lib/python3.6/site-packages/flask/app.py", line 1813, in full_dispatch_request
    rv = self.dispatch_request()
  File "/usr/lib/python3.6/site-packages/flask/app.py", line 1799, in dispatch_request
    return self.view_functions[rule.endpoint](**req.view_args)
  File "Routes.py", line 163, in advanced_search
    db = DB()
  File "/home/centos/wwd/queries.py", line 453, in __init__
    except Error.OperationalError as e:
AttributeError: type object 'Error' has no attribute 'OperationalError'
2018-10-16 20:41:14,459 - flask.app - ERROR - Exception on /all [GET]
Traceback (most recent call last):
  File "/usr/lib/python3.6/site-packages/mysql/connector/network.py", line 509, in open_connection
    self.sock.connect(sockaddr)
ConnectionRefusedError: [Errno 111] Connection refused

During handling of the above exception, another exception occurred:

Traceback (most recent call last):
  File "/home/centos/wwd/queries.py", line 450, in __init__
    self.conn = mysql.connector.connect(user='root', password='p@$sw0rD27', host='127.0.0.1', database='wwd')
  File "/usr/lib/python3.6/site-packages/mysql/connector/__init__.py", line 179, in connect
    return MySQLConnection(*args, **kwargs)
  File "/usr/lib/python3.6/site-packages/mysql/connector/connection.py", line 94, in __init__
    self.connect(**kwargs)
  File "/usr/lib/python3.6/site-packages/mysql/connector/abstracts.py", line 722, in connect
    self._open_connection()
  File "/usr/lib/python3.6/site-packages/mysql/connector/connection.py", line 207, in _open_connection
    self._socket.open_connection()
  File "/usr/lib/python3.6/site-packages/mysql/connector/network.py", line 512, in open_connection
    errno=2003, values=(self.get_address(), _strioerror(err)))
mysql.connector.errors.InterfaceError: 2003: Can't connect to MySQL server on '127.0.0.1:3306' (111 Connection refused)

During handling of the above exception, another exception occurred:

Traceback (most recent call last):
  File "/usr/lib/python3.6/site-packages/flask/app.py", line 2292, in wsgi_app
    response = self.full_dispatch_request()
  File "/usr/lib/python3.6/site-packages/flask/app.py", line 1815, in full_dispatch_request
    rv = self.handle_user_exception(e)
  File "/usr/lib/python3.6/site-packages/flask/app.py", line 1718, in handle_user_exception
    reraise(exc_type, exc_value, tb)
  File "/usr/lib/python3.6/site-packages/flask/_compat.py", line 35, in reraise
    raise value
  File "/usr/lib/python3.6/site-packages/flask/app.py", line 1813, in full_dispatch_request
    rv = self.dispatch_request()
  File "/usr/lib/python3.6/site-packages/flask/app.py", line 1799, in dispatch_request
    return self.view_functions[rule.endpoint](**req.view_args)
  File "Routes.py", line 104, in all_orgs
    db =DB()
  File "/home/centos/wwd/queries.py", line 453, in __init__
    except Error.OperationalError as e:
AttributeError: type object 'Error' has no attribute 'OperationalError'
2018-10-16 20:43:48,040 - flask.app - ERROR - Exception on /all [GET]
Traceback (most recent call last):
  File "/usr/lib/python3.6/site-packages/mysql/connector/network.py", line 509, in open_connection
    self.sock.connect(sockaddr)
ConnectionRefusedError: [Errno 111] Connection refused

During handling of the above exception, another exception occurred:

Traceback (most recent call last):
  File "/home/centos/wwd/queries.py", line 450, in __init__
    self.conn = mysql.connector.connect(user='root', password='p@$sw0rD27', host='localhost', database='wwd')
  File "/usr/lib/python3.6/site-packages/mysql/connector/__init__.py", line 179, in connect
    return MySQLConnection(*args, **kwargs)
  File "/usr/lib/python3.6/site-packages/mysql/connector/connection.py", line 94, in __init__
    self.connect(**kwargs)
  File "/usr/lib/python3.6/site-packages/mysql/connector/abstracts.py", line 722, in connect
    self._open_connection()
  File "/usr/lib/python3.6/site-packages/mysql/connector/connection.py", line 207, in _open_connection
    self._socket.open_connection()
  File "/usr/lib/python3.6/site-packages/mysql/connector/network.py", line 512, in open_connection
    errno=2003, values=(self.get_address(), _strioerror(err)))
mysql.connector.errors.InterfaceError: 2003: Can't connect to MySQL server on 'localhost:3306' (111 Connection refused)

During handling of the above exception, another exception occurred:

Traceback (most recent call last):
  File "/usr/lib/python3.6/site-packages/flask/app.py", line 2292, in wsgi_app
    response = self.full_dispatch_request()
  File "/usr/lib/python3.6/site-packages/flask/app.py", line 1815, in full_dispatch_request
    rv = self.handle_user_exception(e)
  File "/usr/lib/python3.6/site-packages/flask/app.py", line 1718, in handle_user_exception
    reraise(exc_type, exc_value, tb)
  File "/usr/lib/python3.6/site-packages/flask/_compat.py", line 35, in reraise
    raise value
  File "/usr/lib/python3.6/site-packages/flask/app.py", line 1813, in full_dispatch_request
    rv = self.dispatch_request()
  File "/usr/lib/python3.6/site-packages/flask/app.py", line 1799, in dispatch_request
    return self.view_functions[rule.endpoint](**req.view_args)
  File "Routes.py", line 104, in all_orgs
    db =DB()
  File "/home/centos/wwd/queries.py", line 453, in __init__
    except Error.OperationalError as e:
AttributeError: type object 'Error' has no attribute 'OperationalError'
2018-10-16 20:47:27,523 - flask.app - ERROR - Exception on /all [GET]
Traceback (most recent call last):
  File "/home/centos/wwd/queries.py", line 473, in run_query
    cursor.execute(query, args)
  File "/usr/lib/python3.6/site-packages/mysql/connector/cursor.py", line 1168, in execute
    parameters=self._prepared['parameters'])
  File "/usr/lib/python3.6/site-packages/mysql/connector/connection.py", line 983, in cmd_stmt_execute
    long_data_used, self.charset)
  File "/usr/lib/python3.6/site-packages/mysql/connector/protocol.py", line 687, in make_stmt_execute
    classname=value.__class__.__name__))
mysql.connector.errors.ProgrammingError: MySQL binary protocol can not handle 'bytearray' objects

During handling of the above exception, another exception occurred:

Traceback (most recent call last):
  File "/usr/lib/python3.6/site-packages/flask/app.py", line 2292, in wsgi_app
    response = self.full_dispatch_request()
  File "/usr/lib/python3.6/site-packages/flask/app.py", line 1815, in full_dispatch_request
    rv = self.handle_user_exception(e)
  File "/usr/lib/python3.6/site-packages/flask/app.py", line 1718, in handle_user_exception
    reraise(exc_type, exc_value, tb)
  File "/usr/lib/python3.6/site-packages/flask/_compat.py", line 35, in reraise
    raise value
  File "/usr/lib/python3.6/site-packages/flask/app.py", line 1813, in full_dispatch_request
    rv = self.dispatch_request()
  File "/usr/lib/python3.6/site-packages/flask/app.py", line 1799, in dispatch_request
    return self.view_functions[rule.endpoint](**req.view_args)
  File "Routes.py", line 105, in all_orgs
    data = db.get_all_programs_json()
  File "/home/centos/wwd/queries.py", line 547, in get_all_programs_json
    return [pgrm.json_details() for pgrm in self.get_all_programs()]
  File "/home/centos/wwd/queries.py", line 543, in get_all_programs
    return [self.get_program(name) for name in self.get_program_names()]
  File "/home/centos/wwd/queries.py", line 543, in <listcomp>
    return [self.get_program(name) for name in self.get_program_names()]
  File "/home/centos/wwd/queries.py", line 717, in get_program
    results = self.run_query(query, args)
  File "/home/centos/wwd/queries.py", line 475, in run_query
    except Error.OperationalError as e:
AttributeError: type object 'Error' has no attribute 'OperationalError'
2018-10-16 20:50:42,878 - flask.app - ERROR - Exception on /all [GET]
Traceback (most recent call last):
  File "/home/centos/wwd/queries.py", line 473, in run_query
    cursor.execute(query, args)
  File "/usr/lib/python3.6/site-packages/mysql/connector/cursor.py", line 1168, in execute
    parameters=self._prepared['parameters'])
  File "/usr/lib/python3.6/site-packages/mysql/connector/connection.py", line 983, in cmd_stmt_execute
    long_data_used, self.charset)
  File "/usr/lib/python3.6/site-packages/mysql/connector/protocol.py", line 687, in make_stmt_execute
    classname=value.__class__.__name__))
mysql.connector.errors.ProgrammingError: MySQL binary protocol can not handle 'bytearray' objects

During handling of the above exception, another exception occurred:

Traceback (most recent call last):
  File "/usr/lib/python3.6/site-packages/flask/app.py", line 2292, in wsgi_app
    response = self.full_dispatch_request()
  File "/usr/lib/python3.6/site-packages/flask/app.py", line 1815, in full_dispatch_request
    rv = self.handle_user_exception(e)
  File "/usr/lib/python3.6/site-packages/flask/app.py", line 1718, in handle_user_exception
    reraise(exc_type, exc_value, tb)
  File "/usr/lib/python3.6/site-packages/flask/_compat.py", line 35, in reraise
    raise value
  File "/usr/lib/python3.6/site-packages/flask/app.py", line 1813, in full_dispatch_request
    rv = self.dispatch_request()
  File "/usr/lib/python3.6/site-packages/flask/app.py", line 1799, in dispatch_request
    return self.view_functions[rule.endpoint](**req.view_args)
  File "Routes.py", line 105, in all_orgs
    data = db.get_all_programs_json()
  File "/home/centos/wwd/queries.py", line 547, in get_all_programs_json
    return [pgrm.json_details() for pgrm in self.get_all_programs()]
  File "/home/centos/wwd/queries.py", line 543, in get_all_programs
    return [self.get_program(name) for name in self.get_program_names()]
  File "/home/centos/wwd/queries.py", line 543, in <listcomp>
    return [self.get_program(name) for name in self.get_program_names()]
  File "/home/centos/wwd/queries.py", line 717, in get_program
    results = self.run_query(query, args)
  File "/home/centos/wwd/queries.py", line 475, in run_query
    except Error.OperationalError as e:
AttributeError: type object 'Error' has no attribute 'OperationalError'
2018-10-16 20:51:06,134 - flask.app - ERROR - Exception on /all [GET]
Traceback (most recent call last):
  File "/home/centos/wwd/queries.py", line 473, in run_query
    cursor.execute(query, args)
  File "/usr/lib/python3.6/site-packages/mysql/connector/cursor.py", line 1168, in execute
    parameters=self._prepared['parameters'])
  File "/usr/lib/python3.6/site-packages/mysql/connector/connection.py", line 983, in cmd_stmt_execute
    long_data_used, self.charset)
  File "/usr/lib/python3.6/site-packages/mysql/connector/protocol.py", line 687, in make_stmt_execute
    classname=value.__class__.__name__))
mysql.connector.errors.ProgrammingError: MySQL binary protocol can not handle 'bytearray' objects

During handling of the above exception, another exception occurred:

Traceback (most recent call last):
  File "/usr/lib/python3.6/site-packages/flask/app.py", line 2292, in wsgi_app
    response = self.full_dispatch_request()
  File "/usr/lib/python3.6/site-packages/flask/app.py", line 1815, in full_dispatch_request
    rv = self.handle_user_exception(e)
  File "/usr/lib/python3.6/site-packages/flask/app.py", line 1718, in handle_user_exception
    reraise(exc_type, exc_value, tb)
  File "/usr/lib/python3.6/site-packages/flask/_compat.py", line 35, in reraise
    raise value
  File "/usr/lib/python3.6/site-packages/flask/app.py", line 1813, in full_dispatch_request
    rv = self.dispatch_request()
  File "/usr/lib/python3.6/site-packages/flask/app.py", line 1799, in dispatch_request
    return self.view_functions[rule.endpoint](**req.view_args)
  File "Routes.py", line 105, in all_orgs
    data = db.get_all_programs_json()
  File "/home/centos/wwd/queries.py", line 547, in get_all_programs_json
    return [pgrm.json_details() for pgrm in self.get_all_programs()]
  File "/home/centos/wwd/queries.py", line 543, in get_all_programs
    return [self.get_program(name) for name in self.get_program_names()]
  File "/home/centos/wwd/queries.py", line 543, in <listcomp>
    return [self.get_program(name) for name in self.get_program_names()]
  File "/home/centos/wwd/queries.py", line 717, in get_program
    results = self.run_query(query, args)
  File "/home/centos/wwd/queries.py", line 475, in run_query
    except Error.OperationalError as e:
AttributeError: type object 'Error' has no attribute 'OperationalError'
2018-10-17 14:54:02,409 - flask.app - ERROR - Exception on /all [GET]
Traceback (most recent call last):
  File "/home/centos/wwd/queries.py", line 473, in run_query
    cursor.execute(query, args)
  File "/usr/lib/python3.6/site-packages/mysql/connector/cursor.py", line 1168, in execute
    parameters=self._prepared['parameters'])
  File "/usr/lib/python3.6/site-packages/mysql/connector/connection.py", line 983, in cmd_stmt_execute
    long_data_used, self.charset)
  File "/usr/lib/python3.6/site-packages/mysql/connector/protocol.py", line 687, in make_stmt_execute
    classname=value.__class__.__name__))
mysql.connector.errors.ProgrammingError: MySQL binary protocol can not handle 'bytearray' objects

During handling of the above exception, another exception occurred:

Traceback (most recent call last):
  File "/usr/lib/python3.6/site-packages/flask/app.py", line 2292, in wsgi_app
    response = self.full_dispatch_request()
  File "/usr/lib/python3.6/site-packages/flask/app.py", line 1815, in full_dispatch_request
    rv = self.handle_user_exception(e)
  File "/usr/lib/python3.6/site-packages/flask/app.py", line 1718, in handle_user_exception
    reraise(exc_type, exc_value, tb)
  File "/usr/lib/python3.6/site-packages/flask/_compat.py", line 35, in reraise
    raise value
  File "/usr/lib/python3.6/site-packages/flask/app.py", line 1813, in full_dispatch_request
    rv = self.dispatch_request()
  File "/usr/lib/python3.6/site-packages/flask/app.py", line 1799, in dispatch_request
    return self.view_functions[rule.endpoint](**req.view_args)
  File "Routes.py", line 105, in all_orgs
    data = db.get_all_programs_json()
  File "/home/centos/wwd/queries.py", line 547, in get_all_programs_json
    return [pgrm.json_details() for pgrm in self.get_all_programs()]
  File "/home/centos/wwd/queries.py", line 543, in get_all_programs
    return [self.get_program(name) for name in self.get_program_names()]
  File "/home/centos/wwd/queries.py", line 543, in <listcomp>
    return [self.get_program(name) for name in self.get_program_names()]
  File "/home/centos/wwd/queries.py", line 717, in get_program
    results = self.run_query(query, args)
  File "/home/centos/wwd/queries.py", line 475, in run_query
    except Error.OperationalError as e:
AttributeError: type object 'Error' has no attribute 'OperationalError'
2018-10-17 14:57:09,604 - flask.app - ERROR - Exception on /all [GET]
Traceback (most recent call last):
  File "/usr/lib/python3.6/site-packages/flask/app.py", line 2292, in wsgi_app
    response = self.full_dispatch_request()
  File "/usr/lib/python3.6/site-packages/flask/app.py", line 1815, in full_dispatch_request
    rv = self.handle_user_exception(e)
  File "/usr/lib/python3.6/site-packages/flask/app.py", line 1718, in handle_user_exception
    reraise(exc_type, exc_value, tb)
  File "/usr/lib/python3.6/site-packages/flask/_compat.py", line 35, in reraise
    raise value
  File "/usr/lib/python3.6/site-packages/flask/app.py", line 1813, in full_dispatch_request
    rv = self.dispatch_request()
  File "/usr/lib/python3.6/site-packages/flask/app.py", line 1799, in dispatch_request
    return self.view_functions[rule.endpoint](**req.view_args)
  File "Routes.py", line 105, in all_orgs
    data = db.get_all_programs_json()
  File "/home/centos/wwd/queries.py", line 547, in get_all_programs_json
    return [pgrm.json_details() for pgrm in self.get_all_programs()]
  File "/home/centos/wwd/queries.py", line 543, in get_all_programs
    return [self.get_program(name) for name in self.get_program_names()]
  File "/home/centos/wwd/queries.py", line 543, in <listcomp>
    return [self.get_program(name) for name in self.get_program_names()]
  File "/home/centos/wwd/queries.py", line 717, in get_program
    results = self.run_query(query, args)
  File "/home/centos/wwd/queries.py", line 473, in run_query
    cursor.execute(query, args)
  File "/usr/lib/python3.6/site-packages/mysql/connector/cursor.py", line 1168, in execute
    parameters=self._prepared['parameters'])
  File "/usr/lib/python3.6/site-packages/mysql/connector/connection.py", line 983, in cmd_stmt_execute
    long_data_used, self.charset)
  File "/usr/lib/python3.6/site-packages/mysql/connector/protocol.py", line 687, in make_stmt_execute
    classname=value.__class__.__name__))
mysql.connector.errors.ProgrammingError: MySQL binary protocol can not handle 'bytearray' objects
2018-10-17 14:57:48,341 - flask.app - ERROR - Exception on /all [GET]
Traceback (most recent call last):
  File "/usr/lib/python3.6/site-packages/flask/app.py", line 2292, in wsgi_app
    response = self.full_dispatch_request()
  File "/usr/lib/python3.6/site-packages/flask/app.py", line 1815, in full_dispatch_request
    rv = self.handle_user_exception(e)
  File "/usr/lib/python3.6/site-packages/flask/app.py", line 1718, in handle_user_exception
    reraise(exc_type, exc_value, tb)
  File "/usr/lib/python3.6/site-packages/flask/_compat.py", line 35, in reraise
    raise value
  File "/usr/lib/python3.6/site-packages/flask/app.py", line 1813, in full_dispatch_request
    rv = self.dispatch_request()
  File "/usr/lib/python3.6/site-packages/flask/app.py", line 1799, in dispatch_request
    return self.view_functions[rule.endpoint](**req.view_args)
  File "Routes.py", line 105, in all_orgs
    data = db.get_all_programs_json()
  File "/home/centos/wwd/queries.py", line 547, in get_all_programs_json
    return [pgrm.json_details() for pgrm in self.get_all_programs()]
  File "/home/centos/wwd/queries.py", line 543, in get_all_programs
    return [self.get_program(name) for name in self.get_program_names()]
  File "/home/centos/wwd/queries.py", line 543, in <listcomp>
    return [self.get_program(name) for name in self.get_program_names()]
  File "/home/centos/wwd/queries.py", line 717, in get_program
    results = self.run_query(query, args)
  File "/home/centos/wwd/queries.py", line 473, in run_query
    cursor.execute(query, args)
  File "/usr/lib/python3.6/site-packages/mysql/connector/cursor.py", line 1168, in execute
    parameters=self._prepared['parameters'])
  File "/usr/lib/python3.6/site-packages/mysql/connector/connection.py", line 983, in cmd_stmt_execute
    long_data_used, self.charset)
  File "/usr/lib/python3.6/site-packages/mysql/connector/protocol.py", line 687, in make_stmt_execute
    classname=value.__class__.__name__))
mysql.connector.errors.ProgrammingError: MySQL binary protocol can not handle 'bytearray' objects
2018-10-17 14:57:51,612 - flask.app - ERROR - Exception on /all [GET]
Traceback (most recent call last):
  File "/usr/lib/python3.6/site-packages/flask/app.py", line 2292, in wsgi_app
    response = self.full_dispatch_request()
  File "/usr/lib/python3.6/site-packages/flask/app.py", line 1815, in full_dispatch_request
    rv = self.handle_user_exception(e)
  File "/usr/lib/python3.6/site-packages/flask/app.py", line 1718, in handle_user_exception
    reraise(exc_type, exc_value, tb)
  File "/usr/lib/python3.6/site-packages/flask/_compat.py", line 35, in reraise
    raise value
  File "/usr/lib/python3.6/site-packages/flask/app.py", line 1813, in full_dispatch_request
    rv = self.dispatch_request()
  File "/usr/lib/python3.6/site-packages/flask/app.py", line 1799, in dispatch_request
    return self.view_functions[rule.endpoint](**req.view_args)
  File "Routes.py", line 105, in all_orgs
    data = db.get_all_programs_json()
  File "/home/centos/wwd/queries.py", line 547, in get_all_programs_json
    return [pgrm.json_details() for pgrm in self.get_all_programs()]
  File "/home/centos/wwd/queries.py", line 543, in get_all_programs
    return [self.get_program(name) for name in self.get_program_names()]
  File "/home/centos/wwd/queries.py", line 543, in <listcomp>
    return [self.get_program(name) for name in self.get_program_names()]
  File "/home/centos/wwd/queries.py", line 717, in get_program
    results = self.run_query(query, args)
  File "/home/centos/wwd/queries.py", line 473, in run_query
    cursor.execute(query, args)
  File "/usr/lib/python3.6/site-packages/mysql/connector/cursor.py", line 1168, in execute
    parameters=self._prepared['parameters'])
  File "/usr/lib/python3.6/site-packages/mysql/connector/connection.py", line 983, in cmd_stmt_execute
    long_data_used, self.charset)
  File "/usr/lib/python3.6/site-packages/mysql/connector/protocol.py", line 687, in make_stmt_execute
    classname=value.__class__.__name__))
mysql.connector.errors.ProgrammingError: MySQL binary protocol can not handle 'bytearray' objects
2018-10-17 15:00:52,820 - flask.app - ERROR - Exception on /all [GET]
Traceback (most recent call last):
  File "/usr/lib/python3.6/site-packages/flask/app.py", line 2292, in wsgi_app
    response = self.full_dispatch_request()
  File "/usr/lib/python3.6/site-packages/flask/app.py", line 1815, in full_dispatch_request
    rv = self.handle_user_exception(e)
  File "/usr/lib/python3.6/site-packages/flask/app.py", line 1718, in handle_user_exception
    reraise(exc_type, exc_value, tb)
  File "/usr/lib/python3.6/site-packages/flask/_compat.py", line 35, in reraise
    raise value
  File "/usr/lib/python3.6/site-packages/flask/app.py", line 1813, in full_dispatch_request
    rv = self.dispatch_request()
  File "/usr/lib/python3.6/site-packages/flask/app.py", line 1799, in dispatch_request
    return self.view_functions[rule.endpoint](**req.view_args)
  File "Routes.py", line 105, in all_orgs
    data = db.get_all_programs_json()
  File "/home/centos/wwd/queries.py", line 547, in get_all_programs_json
    return [pgrm.json_details() for pgrm in self.get_all_programs()]
  File "/home/centos/wwd/queries.py", line 543, in get_all_programs
    return [self.get_program(name) for name in self.get_program_names()]
  File "/home/centos/wwd/queries.py", line 543, in <listcomp>
    return [self.get_program(name) for name in self.get_program_names()]
  File "/home/centos/wwd/queries.py", line 717, in get_program
    results = self.run_query(query, args)
  File "/home/centos/wwd/queries.py", line 473, in run_query
    cursor.execute(query, args)
  File "/usr/lib/python3.6/site-packages/mysql/connector/cursor.py", line 1168, in execute
    parameters=self._prepared['parameters'])
  File "/usr/lib/python3.6/site-packages/mysql/connector/connection.py", line 983, in cmd_stmt_execute
    long_data_used, self.charset)
  File "/usr/lib/python3.6/site-packages/mysql/connector/protocol.py", line 687, in make_stmt_execute
    classname=value.__class__.__name__))
mysql.connector.errors.ProgrammingError: MySQL binary protocol can not handle 'bytearray' objects
2018-10-17 16:31:16,851 - flask.app - ERROR - Exception on /all [GET]
Traceback (most recent call last):
  File "/usr/lib/python3.6/site-packages/flask/app.py", line 2292, in wsgi_app
    response = self.full_dispatch_request()
  File "/usr/lib/python3.6/site-packages/flask/app.py", line 1815, in full_dispatch_request
    rv = self.handle_user_exception(e)
  File "/usr/lib/python3.6/site-packages/flask/app.py", line 1718, in handle_user_exception
    reraise(exc_type, exc_value, tb)
  File "/usr/lib/python3.6/site-packages/flask/_compat.py", line 35, in reraise
    raise value
  File "/usr/lib/python3.6/site-packages/flask/app.py", line 1813, in full_dispatch_request
    rv = self.dispatch_request()
  File "/usr/lib/python3.6/site-packages/flask/app.py", line 1799, in dispatch_request
    return self.view_functions[rule.endpoint](**req.view_args)
  File "Routes.py", line 105, in all_orgs
    data = db.get_all_programs_json()
  File "/home/centos/wwd/queries.py", line 547, in get_all_programs_json
    return [pgrm.json_details() for pgrm in self.get_all_programs()]
  File "/home/centos/wwd/queries.py", line 543, in get_all_programs
    return [self.get_program(name) for name in self.get_program_names()]
  File "/home/centos/wwd/queries.py", line 543, in <listcomp>
    return [self.get_program(name) for name in self.get_program_names()]
  File "/home/centos/wwd/queries.py", line 717, in get_program
    results = self.run_query(query, args)
  File "/home/centos/wwd/queries.py", line 473, in run_query
    cursor.execute(query, args)
  File "/usr/lib/python3.6/site-packages/mysql/connector/cursor.py", line 1168, in execute
    parameters=self._prepared['parameters'])
  File "/usr/lib/python3.6/site-packages/mysql/connector/connection.py", line 983, in cmd_stmt_execute
    long_data_used, self.charset)
  File "/usr/lib/python3.6/site-packages/mysql/connector/protocol.py", line 687, in make_stmt_execute
    classname=value.__class__.__name__))
mysql.connector.errors.ProgrammingError: MySQL binary protocol can not handle 'bytearray' objects
2018-10-17 18:38:31,104 - flask.app - ERROR - Exception on /all [GET]
Traceback (most recent call last):
  File "/usr/lib/python3.6/site-packages/flask/app.py", line 2292, in wsgi_app
    response = self.full_dispatch_request()
  File "/usr/lib/python3.6/site-packages/flask/app.py", line 1815, in full_dispatch_request
    rv = self.handle_user_exception(e)
  File "/usr/lib/python3.6/site-packages/flask/app.py", line 1718, in handle_user_exception
    reraise(exc_type, exc_value, tb)
  File "/usr/lib/python3.6/site-packages/flask/_compat.py", line 35, in reraise
    raise value
  File "/usr/lib/python3.6/site-packages/flask/app.py", line 1813, in full_dispatch_request
    rv = self.dispatch_request()
  File "/usr/lib/python3.6/site-packages/flask/app.py", line 1799, in dispatch_request
    return self.view_functions[rule.endpoint](**req.view_args)
  File "Routes.py", line 105, in all_orgs
    data = db.get_all_programs_json()
  File "/home/centos/wwd/queries.py", line 547, in get_all_programs_json
    return [pgrm.json_details() for pgrm in self.get_all_programs()]
  File "/home/centos/wwd/queries.py", line 543, in get_all_programs
    return [self.get_program(name) for name in self.get_program_names()]
  File "/home/centos/wwd/queries.py", line 543, in <listcomp>
    return [self.get_program(name) for name in self.get_program_names()]
  File "/home/centos/wwd/queries.py", line 717, in get_program
    results = self.run_query(query, args)
  File "/home/centos/wwd/queries.py", line 473, in run_query
    cursor.execute(query, args)
  File "/usr/lib/python3.6/site-packages/mysql/connector/cursor.py", line 1168, in execute
    parameters=self._prepared['parameters'])
  File "/usr/lib/python3.6/site-packages/mysql/connector/connection.py", line 983, in cmd_stmt_execute
    long_data_used, self.charset)
  File "/usr/lib/python3.6/site-packages/mysql/connector/protocol.py", line 687, in make_stmt_execute
    classname=value.__class__.__name__))
mysql.connector.errors.ProgrammingError: MySQL binary protocol can not handle 'bytearray' objects
2018-10-17 18:44:36,692 - flask.app - ERROR - Exception on /advanced_search [GET]
Traceback (most recent call last):
  File "/usr/lib/python3.6/site-packages/flask/app.py", line 2292, in wsgi_app
    response = self.full_dispatch_request()
  File "/usr/lib/python3.6/site-packages/flask/app.py", line 1815, in full_dispatch_request
    rv = self.handle_user_exception(e)
  File "/usr/lib/python3.6/site-packages/flask/app.py", line 1718, in handle_user_exception
    reraise(exc_type, exc_value, tb)
  File "/usr/lib/python3.6/site-packages/flask/_compat.py", line 35, in reraise
    raise value
  File "/usr/lib/python3.6/site-packages/flask/app.py", line 1813, in full_dispatch_request
    rv = self.dispatch_request()
  File "/usr/lib/python3.6/site-packages/flask/app.py", line 1799, in dispatch_request
    return self.view_functions[rule.endpoint](**req.view_args)
  File "Routes.py", line 164, in advanced_search
    orgs = db.get_program_names()
  File "/home/centos/wwd/queries.py", line 539, in get_program_names
    return [row[0] for row in self.run_query(query)]
  File "/home/centos/wwd/queries.py", line 480, in run_query
    cursor = self.conn.cursor(prepared=True)
  File "/usr/lib64/python3.6/site-packages/mysql/connector/connection_cext.py", line 479, in cursor
    return (types[cursor_type])(self)
  File "/usr/lib64/python3.6/site-packages/mysql/connector/cursor_cext.py", line 818, in __init__
    "Alternative: Use connection.MySQLCursorPrepared")
NotImplementedError: Alternative: Use connection.MySQLCursorPrepared
2018-10-17 18:44:41,437 - flask.app - ERROR - Exception on /advanced_search [GET]
Traceback (most recent call last):
  File "/usr/lib/python3.6/site-packages/flask/app.py", line 2292, in wsgi_app
    response = self.full_dispatch_request()
  File "/usr/lib/python3.6/site-packages/flask/app.py", line 1815, in full_dispatch_request
    rv = self.handle_user_exception(e)
  File "/usr/lib/python3.6/site-packages/flask/app.py", line 1718, in handle_user_exception
    reraise(exc_type, exc_value, tb)
  File "/usr/lib/python3.6/site-packages/flask/_compat.py", line 35, in reraise
    raise value
  File "/usr/lib/python3.6/site-packages/flask/app.py", line 1813, in full_dispatch_request
    rv = self.dispatch_request()
  File "/usr/lib/python3.6/site-packages/flask/app.py", line 1799, in dispatch_request
    return self.view_functions[rule.endpoint](**req.view_args)
  File "Routes.py", line 164, in advanced_search
    orgs = db.get_program_names()
  File "/home/centos/wwd/queries.py", line 539, in get_program_names
    return [row[0] for row in self.run_query(query)]
  File "/home/centos/wwd/queries.py", line 480, in run_query
    cursor = self.conn.cursor(prepared=True)
  File "/usr/lib64/python3.6/site-packages/mysql/connector/connection_cext.py", line 479, in cursor
    return (types[cursor_type])(self)
  File "/usr/lib64/python3.6/site-packages/mysql/connector/cursor_cext.py", line 818, in __init__
    "Alternative: Use connection.MySQLCursorPrepared")
NotImplementedError: Alternative: Use connection.MySQLCursorPrepared
2018-10-17 18:44:51,584 - flask.app - ERROR - Exception on /all [GET]
Traceback (most recent call last):
  File "/usr/lib/python3.6/site-packages/flask/app.py", line 2292, in wsgi_app
    response = self.full_dispatch_request()
  File "/usr/lib/python3.6/site-packages/flask/app.py", line 1815, in full_dispatch_request
    rv = self.handle_user_exception(e)
  File "/usr/lib/python3.6/site-packages/flask/app.py", line 1718, in handle_user_exception
    reraise(exc_type, exc_value, tb)
  File "/usr/lib/python3.6/site-packages/flask/_compat.py", line 35, in reraise
    raise value
  File "/usr/lib/python3.6/site-packages/flask/app.py", line 1813, in full_dispatch_request
    rv = self.dispatch_request()
  File "/usr/lib/python3.6/site-packages/flask/app.py", line 1799, in dispatch_request
    return self.view_functions[rule.endpoint](**req.view_args)
  File "Routes.py", line 105, in all_orgs
    data = db.get_all_programs_json()
  File "/home/centos/wwd/queries.py", line 547, in get_all_programs_json
    return [pgrm.json_details() for pgrm in self.get_all_programs()]
  File "/home/centos/wwd/queries.py", line 543, in get_all_programs
    return [self.get_program(name) for name in self.get_program_names()]
  File "/home/centos/wwd/queries.py", line 539, in get_program_names
    return [row[0] for row in self.run_query(query)]
  File "/home/centos/wwd/queries.py", line 480, in run_query
    cursor = self.conn.cursor(prepared=True)
  File "/usr/lib64/python3.6/site-packages/mysql/connector/connection_cext.py", line 479, in cursor
    return (types[cursor_type])(self)
  File "/usr/lib64/python3.6/site-packages/mysql/connector/cursor_cext.py", line 818, in __init__
    "Alternative: Use connection.MySQLCursorPrepared")
NotImplementedError: Alternative: Use connection.MySQLCursorPrepared
2018-10-17 18:48:02,680 - flask.app - ERROR - Exception on /advanced_search [GET]
Traceback (most recent call last):
  File "/usr/lib/python3.6/site-packages/flask/app.py", line 2292, in wsgi_app
    response = self.full_dispatch_request()
  File "/usr/lib/python3.6/site-packages/flask/app.py", line 1815, in full_dispatch_request
    rv = self.handle_user_exception(e)
  File "/usr/lib/python3.6/site-packages/flask/app.py", line 1718, in handle_user_exception
    reraise(exc_type, exc_value, tb)
  File "/usr/lib/python3.6/site-packages/flask/_compat.py", line 35, in reraise
    raise value
  File "/usr/lib/python3.6/site-packages/flask/app.py", line 1813, in full_dispatch_request
    rv = self.dispatch_request()
  File "/usr/lib/python3.6/site-packages/flask/app.py", line 1799, in dispatch_request
    return self.view_functions[rule.endpoint](**req.view_args)
  File "Routes.py", line 164, in advanced_search
    orgs = db.get_program_names()
  File "/home/centos/wwd/queries.py", line 539, in get_program_names
    return [row[0] for row in self.run_query(query)]
  File "/home/centos/wwd/queries.py", line 480, in run_query
    cursor = self.conn.cursor(prepared=True)
  File "/usr/lib64/python3.6/site-packages/mysql/connector/connection_cext.py", line 479, in cursor
    return (types[cursor_type])(self)
  File "/usr/lib64/python3.6/site-packages/mysql/connector/cursor_cext.py", line 818, in __init__
    "Alternative: Use connection.MySQLCursorPrepared")
NotImplementedError: Alternative: Use connection.MySQLCursorPrepared
2018-10-17 18:48:04,486 - flask.app - ERROR - Exception on /advanced_search [GET]
Traceback (most recent call last):
  File "/usr/lib/python3.6/site-packages/flask/app.py", line 2292, in wsgi_app
    response = self.full_dispatch_request()
  File "/usr/lib/python3.6/site-packages/flask/app.py", line 1815, in full_dispatch_request
    rv = self.handle_user_exception(e)
  File "/usr/lib/python3.6/site-packages/flask/app.py", line 1718, in handle_user_exception
    reraise(exc_type, exc_value, tb)
  File "/usr/lib/python3.6/site-packages/flask/_compat.py", line 35, in reraise
    raise value
  File "/usr/lib/python3.6/site-packages/flask/app.py", line 1813, in full_dispatch_request
    rv = self.dispatch_request()
  File "/usr/lib/python3.6/site-packages/flask/app.py", line 1799, in dispatch_request
    return self.view_functions[rule.endpoint](**req.view_args)
  File "Routes.py", line 164, in advanced_search
    orgs = db.get_program_names()
  File "/home/centos/wwd/queries.py", line 539, in get_program_names
    return [row[0] for row in self.run_query(query)]
  File "/home/centos/wwd/queries.py", line 480, in run_query
    cursor = self.conn.cursor(prepared=True)
  File "/usr/lib64/python3.6/site-packages/mysql/connector/connection_cext.py", line 479, in cursor
    return (types[cursor_type])(self)
  File "/usr/lib64/python3.6/site-packages/mysql/connector/cursor_cext.py", line 818, in __init__
    "Alternative: Use connection.MySQLCursorPrepared")
NotImplementedError: Alternative: Use connection.MySQLCursorPrepared
2018-10-17 18:48:16,578 - flask.app - ERROR - Exception on /advanced_search [GET]
Traceback (most recent call last):
  File "/usr/lib/python3.6/site-packages/flask/app.py", line 2292, in wsgi_app
    response = self.full_dispatch_request()
  File "/usr/lib/python3.6/site-packages/flask/app.py", line 1815, in full_dispatch_request
    rv = self.handle_user_exception(e)
  File "/usr/lib/python3.6/site-packages/flask/app.py", line 1718, in handle_user_exception
    reraise(exc_type, exc_value, tb)
  File "/usr/lib/python3.6/site-packages/flask/_compat.py", line 35, in reraise
    raise value
  File "/usr/lib/python3.6/site-packages/flask/app.py", line 1813, in full_dispatch_request
    rv = self.dispatch_request()
  File "/usr/lib/python3.6/site-packages/flask/app.py", line 1799, in dispatch_request
    return self.view_functions[rule.endpoint](**req.view_args)
  File "Routes.py", line 164, in advanced_search
    orgs = db.get_program_names()
  File "/home/centos/wwd/queries.py", line 539, in get_program_names
    return [row[0] for row in self.run_query(query)]
  File "/home/centos/wwd/queries.py", line 480, in run_query
    cursor = self.conn.cursor(prepared=True)
  File "/usr/lib64/python3.6/site-packages/mysql/connector/connection_cext.py", line 479, in cursor
    return (types[cursor_type])(self)
  File "/usr/lib64/python3.6/site-packages/mysql/connector/cursor_cext.py", line 818, in __init__
    "Alternative: Use connection.MySQLCursorPrepared")
NotImplementedError: Alternative: Use connection.MySQLCursorPrepared
2018-10-17 18:53:38,571 - flask.app - ERROR - Exception on /advanced_search [GET]
Traceback (most recent call last):
  File "/usr/lib/python3.6/site-packages/flask/app.py", line 2292, in wsgi_app
    response = self.full_dispatch_request()
  File "/usr/lib/python3.6/site-packages/flask/app.py", line 1815, in full_dispatch_request
    rv = self.handle_user_exception(e)
  File "/usr/lib/python3.6/site-packages/flask/app.py", line 1718, in handle_user_exception
    reraise(exc_type, exc_value, tb)
  File "/usr/lib/python3.6/site-packages/flask/_compat.py", line 35, in reraise
    raise value
  File "/usr/lib/python3.6/site-packages/flask/app.py", line 1813, in full_dispatch_request
    rv = self.dispatch_request()
  File "/usr/lib/python3.6/site-packages/flask/app.py", line 1799, in dispatch_request
    return self.view_functions[rule.endpoint](**req.view_args)
  File "Routes.py", line 164, in advanced_search
    orgs = db.get_program_names()
  File "/home/centos/wwd/queries.py", line 540, in get_program_names
    return [row[0] for row in self.run_query(query)]
  File "/home/centos/wwd/queries.py", line 482, in run_query
    cursor.execute(query)
  File "/usr/lib64/python3.6/site-packages/mysql/connector/cursor.py", line 1195, in execute
    self._prepared = self._connection.cmd_stmt_prepare(operation)
  File "/usr/lib64/python3.6/site-packages/mysql/connector/abstracts.py", line 964, in cmd_stmt_prepare
    raise NotImplementedError
NotImplementedError
2018-10-17 18:53:41,506 - flask.app - ERROR - Exception on /advanced_search [GET]
Traceback (most recent call last):
  File "/usr/lib/python3.6/site-packages/flask/app.py", line 2292, in wsgi_app
    response = self.full_dispatch_request()
  File "/usr/lib/python3.6/site-packages/flask/app.py", line 1815, in full_dispatch_request
    rv = self.handle_user_exception(e)
  File "/usr/lib/python3.6/site-packages/flask/app.py", line 1718, in handle_user_exception
    reraise(exc_type, exc_value, tb)
  File "/usr/lib/python3.6/site-packages/flask/_compat.py", line 35, in reraise
    raise value
  File "/usr/lib/python3.6/site-packages/flask/app.py", line 1813, in full_dispatch_request
    rv = self.dispatch_request()
  File "/usr/lib/python3.6/site-packages/flask/app.py", line 1799, in dispatch_request
    return self.view_functions[rule.endpoint](**req.view_args)
  File "Routes.py", line 164, in advanced_search
    orgs = db.get_program_names()
  File "/home/centos/wwd/queries.py", line 540, in get_program_names
    return [row[0] for row in self.run_query(query)]
  File "/home/centos/wwd/queries.py", line 482, in run_query
    cursor.execute(query)
  File "/usr/lib64/python3.6/site-packages/mysql/connector/cursor.py", line 1195, in execute
    self._prepared = self._connection.cmd_stmt_prepare(operation)
  File "/usr/lib64/python3.6/site-packages/mysql/connector/abstracts.py", line 964, in cmd_stmt_prepare
    raise NotImplementedError
NotImplementedError
2018-10-17 18:53:42,412 - flask.app - ERROR - Exception on /all [GET]
Traceback (most recent call last):
  File "/usr/lib/python3.6/site-packages/flask/app.py", line 2292, in wsgi_app
    response = self.full_dispatch_request()
  File "/usr/lib/python3.6/site-packages/flask/app.py", line 1815, in full_dispatch_request
    rv = self.handle_user_exception(e)
  File "/usr/lib/python3.6/site-packages/flask/app.py", line 1718, in handle_user_exception
    reraise(exc_type, exc_value, tb)
  File "/usr/lib/python3.6/site-packages/flask/_compat.py", line 35, in reraise
    raise value
  File "/usr/lib/python3.6/site-packages/flask/app.py", line 1813, in full_dispatch_request
    rv = self.dispatch_request()
  File "/usr/lib/python3.6/site-packages/flask/app.py", line 1799, in dispatch_request
    return self.view_functions[rule.endpoint](**req.view_args)
  File "Routes.py", line 105, in all_orgs
    data = db.get_all_programs_json()
  File "/home/centos/wwd/queries.py", line 548, in get_all_programs_json
    return [pgrm.json_details() for pgrm in self.get_all_programs()]
  File "/home/centos/wwd/queries.py", line 544, in get_all_programs
    return [self.get_program(name) for name in self.get_program_names()]
  File "/home/centos/wwd/queries.py", line 540, in get_program_names
    return [row[0] for row in self.run_query(query)]
  File "/home/centos/wwd/queries.py", line 482, in run_query
    cursor.execute(query)
  File "/usr/lib64/python3.6/site-packages/mysql/connector/cursor.py", line 1195, in execute
    self._prepared = self._connection.cmd_stmt_prepare(operation)
  File "/usr/lib64/python3.6/site-packages/mysql/connector/abstracts.py", line 964, in cmd_stmt_prepare
    raise NotImplementedError
NotImplementedError
2018-10-17 18:55:12,710 - flask.app - ERROR - Exception on /advanced_search [GET]
Traceback (most recent call last):
  File "/usr/lib/python3.6/site-packages/flask/app.py", line 2292, in wsgi_app
    response = self.full_dispatch_request()
  File "/usr/lib/python3.6/site-packages/flask/app.py", line 1815, in full_dispatch_request
    rv = self.handle_user_exception(e)
  File "/usr/lib/python3.6/site-packages/flask/app.py", line 1718, in handle_user_exception
    reraise(exc_type, exc_value, tb)
  File "/usr/lib/python3.6/site-packages/flask/_compat.py", line 35, in reraise
    raise value
  File "/usr/lib/python3.6/site-packages/flask/app.py", line 1813, in full_dispatch_request
    rv = self.dispatch_request()
  File "/usr/lib/python3.6/site-packages/flask/app.py", line 1799, in dispatch_request
    return self.view_functions[rule.endpoint](**req.view_args)
  File "Routes.py", line 164, in advanced_search
    orgs = db.get_program_names()
  File "/home/centos/wwd/queries.py", line 540, in get_program_names
    return [row[0] for row in self.run_query(query)]
  File "/home/centos/wwd/queries.py", line 482, in run_query
    cursor.execute(query)
  File "/usr/lib64/python3.6/site-packages/mysql/connector/cursor.py", line 1195, in execute
    self._prepared = self._connection.cmd_stmt_prepare(operation)
  File "/usr/lib64/python3.6/site-packages/mysql/connector/abstracts.py", line 964, in cmd_stmt_prepare
    raise NotImplementedError
NotImplementedError
2018-10-17 18:55:19,052 - flask.app - ERROR - Exception on /all [GET]
Traceback (most recent call last):
  File "/usr/lib/python3.6/site-packages/flask/app.py", line 2292, in wsgi_app
    response = self.full_dispatch_request()
  File "/usr/lib/python3.6/site-packages/flask/app.py", line 1815, in full_dispatch_request
    rv = self.handle_user_exception(e)
  File "/usr/lib/python3.6/site-packages/flask/app.py", line 1718, in handle_user_exception
    reraise(exc_type, exc_value, tb)
  File "/usr/lib/python3.6/site-packages/flask/_compat.py", line 35, in reraise
    raise value
  File "/usr/lib/python3.6/site-packages/flask/app.py", line 1813, in full_dispatch_request
    rv = self.dispatch_request()
  File "/usr/lib/python3.6/site-packages/flask/app.py", line 1799, in dispatch_request
    return self.view_functions[rule.endpoint](**req.view_args)
  File "Routes.py", line 105, in all_orgs
    data = db.get_all_programs_json()
  File "/home/centos/wwd/queries.py", line 548, in get_all_programs_json
    return [pgrm.json_details() for pgrm in self.get_all_programs()]
  File "/home/centos/wwd/queries.py", line 544, in get_all_programs
    return [self.get_program(name) for name in self.get_program_names()]
  File "/home/centos/wwd/queries.py", line 540, in get_program_names
    return [row[0] for row in self.run_query(query)]
  File "/home/centos/wwd/queries.py", line 482, in run_query
    cursor.execute(query)
  File "/usr/lib64/python3.6/site-packages/mysql/connector/cursor.py", line 1195, in execute
    self._prepared = self._connection.cmd_stmt_prepare(operation)
  File "/usr/lib64/python3.6/site-packages/mysql/connector/abstracts.py", line 964, in cmd_stmt_prepare
    raise NotImplementedError
NotImplementedError
2018-10-17 18:55:20,343 - flask.app - ERROR - Exception on /all [GET]
Traceback (most recent call last):
  File "/usr/lib/python3.6/site-packages/flask/app.py", line 2292, in wsgi_app
    response = self.full_dispatch_request()
  File "/usr/lib/python3.6/site-packages/flask/app.py", line 1815, in full_dispatch_request
    rv = self.handle_user_exception(e)
  File "/usr/lib/python3.6/site-packages/flask/app.py", line 1718, in handle_user_exception
    reraise(exc_type, exc_value, tb)
  File "/usr/lib/python3.6/site-packages/flask/_compat.py", line 35, in reraise
    raise value
  File "/usr/lib/python3.6/site-packages/flask/app.py", line 1813, in full_dispatch_request
    rv = self.dispatch_request()
  File "/usr/lib/python3.6/site-packages/flask/app.py", line 1799, in dispatch_request
    return self.view_functions[rule.endpoint](**req.view_args)
  File "Routes.py", line 105, in all_orgs
    data = db.get_all_programs_json()
  File "/home/centos/wwd/queries.py", line 548, in get_all_programs_json
    return [pgrm.json_details() for pgrm in self.get_all_programs()]
  File "/home/centos/wwd/queries.py", line 544, in get_all_programs
    return [self.get_program(name) for name in self.get_program_names()]
  File "/home/centos/wwd/queries.py", line 540, in get_program_names
    return [row[0] for row in self.run_query(query)]
  File "/home/centos/wwd/queries.py", line 482, in run_query
    cursor.execute(query)
  File "/usr/lib64/python3.6/site-packages/mysql/connector/cursor.py", line 1195, in execute
    self._prepared = self._connection.cmd_stmt_prepare(operation)
  File "/usr/lib64/python3.6/site-packages/mysql/connector/abstracts.py", line 964, in cmd_stmt_prepare
    raise NotImplementedError
NotImplementedError
2018-10-17 18:55:36,576 - flask.app - ERROR - Exception on /all [GET]
Traceback (most recent call last):
  File "/usr/lib/python3.6/site-packages/flask/app.py", line 2292, in wsgi_app
    response = self.full_dispatch_request()
  File "/usr/lib/python3.6/site-packages/flask/app.py", line 1815, in full_dispatch_request
    rv = self.handle_user_exception(e)
  File "/usr/lib/python3.6/site-packages/flask/app.py", line 1718, in handle_user_exception
    reraise(exc_type, exc_value, tb)
  File "/usr/lib/python3.6/site-packages/flask/_compat.py", line 35, in reraise
    raise value
  File "/usr/lib/python3.6/site-packages/flask/app.py", line 1813, in full_dispatch_request
    rv = self.dispatch_request()
  File "/usr/lib/python3.6/site-packages/flask/app.py", line 1799, in dispatch_request
    return self.view_functions[rule.endpoint](**req.view_args)
  File "Routes.py", line 105, in all_orgs
    data = db.get_all_programs_json()
  File "/home/centos/wwd/queries.py", line 548, in get_all_programs_json
    return [pgrm.json_details() for pgrm in self.get_all_programs()]
  File "/home/centos/wwd/queries.py", line 544, in get_all_programs
    return [self.get_program(name) for name in self.get_program_names()]
  File "/home/centos/wwd/queries.py", line 540, in get_program_names
    return [row[0] for row in self.run_query(query)]
  File "/home/centos/wwd/queries.py", line 482, in run_query
    cursor.execute(query)
  File "/usr/lib64/python3.6/site-packages/mysql/connector/cursor.py", line 1195, in execute
    self._prepared = self._connection.cmd_stmt_prepare(operation)
  File "/usr/lib64/python3.6/site-packages/mysql/connector/abstracts.py", line 964, in cmd_stmt_prepare
    raise NotImplementedError
NotImplementedError
2018-10-17 19:22:42,703 - flask.app - ERROR - Exception on /advanced_search [GET]
Traceback (most recent call last):
  File "/usr/lib/python3.6/site-packages/flask/app.py", line 2292, in wsgi_app
    response = self.full_dispatch_request()
  File "/usr/lib/python3.6/site-packages/flask/app.py", line 1815, in full_dispatch_request
    rv = self.handle_user_exception(e)
  File "/usr/lib/python3.6/site-packages/flask/app.py", line 1718, in handle_user_exception
    reraise(exc_type, exc_value, tb)
  File "/usr/lib/python3.6/site-packages/flask/_compat.py", line 35, in reraise
    raise value
  File "/usr/lib/python3.6/site-packages/flask/app.py", line 1813, in full_dispatch_request
    rv = self.dispatch_request()
  File "/usr/lib/python3.6/site-packages/flask/app.py", line 1799, in dispatch_request
    return self.view_functions[rule.endpoint](**req.view_args)
  File "Routes.py", line 164, in advanced_search
    orgs = db.get_program_names()
  File "/home/centos/wwd/queries.py", line 539, in get_program_names
    return [row[0] for row in self.run_query(query)]
  File "/home/centos/wwd/queries.py", line 480, in run_query
    cursor = self.conn.cursor(prepared=True)
  File "/usr/lib64/python3.6/site-packages/mysql/connector/connection_cext.py", line 479, in cursor
    return (types[cursor_type])(self)
  File "/usr/lib64/python3.6/site-packages/mysql/connector/cursor_cext.py", line 818, in __init__
    "Alternative: Use connection.MySQLCursorPrepared")
NotImplementedError: Alternative: Use connection.MySQLCursorPrepared
2018-10-17 19:22:44,610 - flask.app - ERROR - Exception on /advanced_search [GET]
Traceback (most recent call last):
  File "/usr/lib/python3.6/site-packages/flask/app.py", line 2292, in wsgi_app
    response = self.full_dispatch_request()
  File "/usr/lib/python3.6/site-packages/flask/app.py", line 1815, in full_dispatch_request
    rv = self.handle_user_exception(e)
  File "/usr/lib/python3.6/site-packages/flask/app.py", line 1718, in handle_user_exception
    reraise(exc_type, exc_value, tb)
  File "/usr/lib/python3.6/site-packages/flask/_compat.py", line 35, in reraise
    raise value
  File "/usr/lib/python3.6/site-packages/flask/app.py", line 1813, in full_dispatch_request
    rv = self.dispatch_request()
  File "/usr/lib/python3.6/site-packages/flask/app.py", line 1799, in dispatch_request
    return self.view_functions[rule.endpoint](**req.view_args)
  File "Routes.py", line 164, in advanced_search
    orgs = db.get_program_names()
  File "/home/centos/wwd/queries.py", line 539, in get_program_names
    return [row[0] for row in self.run_query(query)]
  File "/home/centos/wwd/queries.py", line 480, in run_query
    cursor = self.conn.cursor(prepared=True)
  File "/usr/lib64/python3.6/site-packages/mysql/connector/connection_cext.py", line 479, in cursor
    return (types[cursor_type])(self)
  File "/usr/lib64/python3.6/site-packages/mysql/connector/cursor_cext.py", line 818, in __init__
    "Alternative: Use connection.MySQLCursorPrepared")
NotImplementedError: Alternative: Use connection.MySQLCursorPrepared
2018-10-18 21:35:51,045 - flask.app - ERROR - Exception on /all [GET]
Traceback (most recent call last):
  File "/opt/wwd/lib64/python3.6/site-packages/flask/app.py", line 2292, in wsgi_app
    response = self.full_dispatch_request()
  File "/opt/wwd/lib64/python3.6/site-packages/flask/app.py", line 1815, in full_dispatch_request
    rv = self.handle_user_exception(e)
  File "/opt/wwd/lib64/python3.6/site-packages/flask/app.py", line 1718, in handle_user_exception
    reraise(exc_type, exc_value, tb)
  File "/opt/wwd/lib64/python3.6/site-packages/flask/_compat.py", line 35, in reraise
    raise value
  File "/opt/wwd/lib64/python3.6/site-packages/flask/app.py", line 1813, in full_dispatch_request
    rv = self.dispatch_request()
  File "/opt/wwd/lib64/python3.6/site-packages/flask/app.py", line 1799, in dispatch_request
    return self.view_functions[rule.endpoint](**req.view_args)
  File "./Routes.py", line 105, in all_orgs
    data = db.get_all_programs_json()
  File "./queries.py", line 548, in get_all_programs_json
    return [pgrm.json_details() for pgrm in self.get_all_programs()]
  File "./queries.py", line 544, in get_all_programs
    return [self.get_program(name) for name in self.get_program_names()]
  File "./queries.py", line 544, in <listcomp>
    return [self.get_program(name) for name in self.get_program_names()]
  File "./queries.py", line 718, in get_program
    results = self.run_query(query, args)
  File "./queries.py", line 474, in run_query
    cursor.execute(query, args)
  File "/opt/wwd/lib64/python3.6/site-packages/mysql/connector/cursor.py", line 1168, in execute
    parameters=self._prepared['parameters'])
  File "/opt/wwd/lib64/python3.6/site-packages/mysql/connector/connection.py", line 983, in cmd_stmt_execute
    long_data_used, self.charset)
  File "/opt/wwd/lib64/python3.6/site-packages/mysql/connector/protocol.py", line 687, in make_stmt_execute
    classname=value.__class__.__name__))
mysql.connector.errors.ProgrammingError: MySQL binary protocol can not handle 'bytearray' objects
2018-10-18 21:35:51,431 - flask.app - ERROR - Exception on /all [GET]
Traceback (most recent call last):
  File "/opt/wwd/lib64/python3.6/site-packages/flask/app.py", line 2292, in wsgi_app
    response = self.full_dispatch_request()
  File "/opt/wwd/lib64/python3.6/site-packages/flask/app.py", line 1815, in full_dispatch_request
    rv = self.handle_user_exception(e)
  File "/opt/wwd/lib64/python3.6/site-packages/flask/app.py", line 1718, in handle_user_exception
    reraise(exc_type, exc_value, tb)
  File "/opt/wwd/lib64/python3.6/site-packages/flask/_compat.py", line 35, in reraise
    raise value
  File "/opt/wwd/lib64/python3.6/site-packages/flask/app.py", line 1813, in full_dispatch_request
    rv = self.dispatch_request()
  File "/opt/wwd/lib64/python3.6/site-packages/flask/app.py", line 1799, in dispatch_request
    return self.view_functions[rule.endpoint](**req.view_args)
  File "./Routes.py", line 105, in all_orgs
    data = db.get_all_programs_json()
  File "./queries.py", line 548, in get_all_programs_json
    return [pgrm.json_details() for pgrm in self.get_all_programs()]
  File "./queries.py", line 544, in get_all_programs
    return [self.get_program(name) for name in self.get_program_names()]
  File "./queries.py", line 544, in <listcomp>
    return [self.get_program(name) for name in self.get_program_names()]
  File "./queries.py", line 718, in get_program
    results = self.run_query(query, args)
  File "./queries.py", line 474, in run_query
    cursor.execute(query, args)
  File "/opt/wwd/lib64/python3.6/site-packages/mysql/connector/cursor.py", line 1168, in execute
    parameters=self._prepared['parameters'])
  File "/opt/wwd/lib64/python3.6/site-packages/mysql/connector/connection.py", line 983, in cmd_stmt_execute
    long_data_used, self.charset)
  File "/opt/wwd/lib64/python3.6/site-packages/mysql/connector/protocol.py", line 687, in make_stmt_execute
    classname=value.__class__.__name__))
mysql.connector.errors.ProgrammingError: MySQL binary protocol can not handle 'bytearray' objects
2018-10-18 21:53:59,215 - flask.app - ERROR - Exception on /all [GET]
Traceback (most recent call last):
  File "/opt/wwd/lib64/python3.6/site-packages/flask/app.py", line 2292, in wsgi_app
    response = self.full_dispatch_request()
  File "/opt/wwd/lib64/python3.6/site-packages/flask/app.py", line 1815, in full_dispatch_request
    rv = self.handle_user_exception(e)
  File "/opt/wwd/lib64/python3.6/site-packages/flask/app.py", line 1718, in handle_user_exception
    reraise(exc_type, exc_value, tb)
  File "/opt/wwd/lib64/python3.6/site-packages/flask/_compat.py", line 35, in reraise
    raise value
  File "/opt/wwd/lib64/python3.6/site-packages/flask/app.py", line 1813, in full_dispatch_request
    rv = self.dispatch_request()
  File "/opt/wwd/lib64/python3.6/site-packages/flask/app.py", line 1799, in dispatch_request
    return self.view_functions[rule.endpoint](**req.view_args)
  File "./Routes.py", line 105, in all_orgs
    data = db.get_all_programs_json()
  File "./queries.py", line 548, in get_all_programs_json
    return [pgrm.json_details() for pgrm in self.get_all_programs()]
  File "./queries.py", line 544, in get_all_programs
    return [self.get_program(name) for name in self.get_program_names()]
  File "./queries.py", line 544, in <listcomp>
    return [self.get_program(name) for name in self.get_program_names()]
  File "./queries.py", line 718, in get_program
    results = self.run_query(query, args)
  File "./queries.py", line 474, in run_query
    cursor.execute(query, args)
  File "/opt/wwd/lib64/python3.6/site-packages/mysql/connector/cursor.py", line 1168, in execute
    parameters=self._prepared['parameters'])
  File "/opt/wwd/lib64/python3.6/site-packages/mysql/connector/connection.py", line 983, in cmd_stmt_execute
    long_data_used, self.charset)
  File "/opt/wwd/lib64/python3.6/site-packages/mysql/connector/protocol.py", line 687, in make_stmt_execute
    classname=value.__class__.__name__))
mysql.connector.errors.ProgrammingError: MySQL binary protocol can not handle 'bytearray' objects
2018-10-18 21:54:26,875 - flask.app - ERROR - Exception on /all [GET]
Traceback (most recent call last):
  File "/opt/wwd/lib64/python3.6/site-packages/flask/app.py", line 2292, in wsgi_app
    response = self.full_dispatch_request()
  File "/opt/wwd/lib64/python3.6/site-packages/flask/app.py", line 1815, in full_dispatch_request
    rv = self.handle_user_exception(e)
  File "/opt/wwd/lib64/python3.6/site-packages/flask/app.py", line 1718, in handle_user_exception
    reraise(exc_type, exc_value, tb)
  File "/opt/wwd/lib64/python3.6/site-packages/flask/_compat.py", line 35, in reraise
    raise value
  File "/opt/wwd/lib64/python3.6/site-packages/flask/app.py", line 1813, in full_dispatch_request
    rv = self.dispatch_request()
  File "/opt/wwd/lib64/python3.6/site-packages/flask/app.py", line 1799, in dispatch_request
    return self.view_functions[rule.endpoint](**req.view_args)
  File "./Routes.py", line 105, in all_orgs
    data = db.get_all_programs_json()
  File "./queries.py", line 548, in get_all_programs_json
    return [pgrm.json_details() for pgrm in self.get_all_programs()]
  File "./queries.py", line 544, in get_all_programs
    return [self.get_program(name) for name in self.get_program_names()]
  File "./queries.py", line 544, in <listcomp>
    return [self.get_program(name) for name in self.get_program_names()]
  File "./queries.py", line 718, in get_program
    results = self.run_query(query, args)
  File "./queries.py", line 474, in run_query
    cursor.execute(query, args)
  File "/opt/wwd/lib64/python3.6/site-packages/mysql/connector/cursor.py", line 1168, in execute
    parameters=self._prepared['parameters'])
  File "/opt/wwd/lib64/python3.6/site-packages/mysql/connector/connection.py", line 983, in cmd_stmt_execute
    long_data_used, self.charset)
  File "/opt/wwd/lib64/python3.6/site-packages/mysql/connector/protocol.py", line 687, in make_stmt_execute
    classname=value.__class__.__name__))
mysql.connector.errors.ProgrammingError: MySQL binary protocol can not handle 'bytearray' objects
2018-10-18 21:55:03,662 - flask.app - ERROR - Exception on /all [GET]
Traceback (most recent call last):
  File "/opt/wwd/lib64/python3.6/site-packages/flask/app.py", line 2292, in wsgi_app
    response = self.full_dispatch_request()
  File "/opt/wwd/lib64/python3.6/site-packages/flask/app.py", line 1815, in full_dispatch_request
    rv = self.handle_user_exception(e)
  File "/opt/wwd/lib64/python3.6/site-packages/flask/app.py", line 1718, in handle_user_exception
    reraise(exc_type, exc_value, tb)
  File "/opt/wwd/lib64/python3.6/site-packages/flask/_compat.py", line 35, in reraise
    raise value
  File "/opt/wwd/lib64/python3.6/site-packages/flask/app.py", line 1813, in full_dispatch_request
    rv = self.dispatch_request()
  File "/opt/wwd/lib64/python3.6/site-packages/flask/app.py", line 1799, in dispatch_request
    return self.view_functions[rule.endpoint](**req.view_args)
  File "./Routes.py", line 105, in all_orgs
    data = db.get_all_programs_json()
  File "./queries.py", line 548, in get_all_programs_json
    return [pgrm.json_details() for pgrm in self.get_all_programs()]
  File "./queries.py", line 544, in get_all_programs
    return [self.get_program(name) for name in self.get_program_names()]
  File "./queries.py", line 544, in <listcomp>
    return [self.get_program(name) for name in self.get_program_names()]
  File "./queries.py", line 718, in get_program
    results = self.run_query(query, args)
  File "./queries.py", line 474, in run_query
    cursor.execute(query, args)
  File "/opt/wwd/lib64/python3.6/site-packages/mysql/connector/cursor.py", line 1168, in execute
    parameters=self._prepared['parameters'])
  File "/opt/wwd/lib64/python3.6/site-packages/mysql/connector/connection.py", line 983, in cmd_stmt_execute
    long_data_used, self.charset)
  File "/opt/wwd/lib64/python3.6/site-packages/mysql/connector/protocol.py", line 687, in make_stmt_execute
    classname=value.__class__.__name__))
mysql.connector.errors.ProgrammingError: MySQL binary protocol can not handle 'bytearray' objects
2018-10-18 22:14:29,910 - flask.app - ERROR - Exception on /all [GET]
Traceback (most recent call last):
  File "/opt/wwd/lib64/python3.6/site-packages/flask/app.py", line 2292, in wsgi_app
    response = self.full_dispatch_request()
  File "/opt/wwd/lib64/python3.6/site-packages/flask/app.py", line 1815, in full_dispatch_request
    rv = self.handle_user_exception(e)
  File "/opt/wwd/lib64/python3.6/site-packages/flask/app.py", line 1718, in handle_user_exception
    reraise(exc_type, exc_value, tb)
  File "/opt/wwd/lib64/python3.6/site-packages/flask/_compat.py", line 35, in reraise
    raise value
  File "/opt/wwd/lib64/python3.6/site-packages/flask/app.py", line 1813, in full_dispatch_request
    rv = self.dispatch_request()
  File "/opt/wwd/lib64/python3.6/site-packages/flask/app.py", line 1799, in dispatch_request
    return self.view_functions[rule.endpoint](**req.view_args)
  File "./Routes.py", line 105, in all_orgs
    data = db.get_all_programs_json()
  File "./queries.py", line 548, in get_all_programs_json
    return [pgrm.json_details() for pgrm in self.get_all_programs()]
  File "./queries.py", line 544, in get_all_programs
    return [self.get_program(name) for name in self.get_program_names()]
  File "./queries.py", line 544, in <listcomp>
    return [self.get_program(name) for name in self.get_program_names()]
  File "./queries.py", line 718, in get_program
    results = self.run_query(query, args)
  File "./queries.py", line 474, in run_query
    cursor.execute(query, args)
  File "/opt/wwd/lib64/python3.6/site-packages/mysql/connector/cursor.py", line 1168, in execute
    parameters=self._prepared['parameters'])
  File "/opt/wwd/lib64/python3.6/site-packages/mysql/connector/connection.py", line 983, in cmd_stmt_execute
    long_data_used, self.charset)
  File "/opt/wwd/lib64/python3.6/site-packages/mysql/connector/protocol.py", line 687, in make_stmt_execute
    classname=value.__class__.__name__))
mysql.connector.errors.ProgrammingError: MySQL binary protocol can not handle 'bytearray' objects
2018-10-19 18:24:19,111 - flask.app - ERROR - Exception on /all [GET]
Traceback (most recent call last):
  File "/opt/wwd/lib64/python3.6/site-packages/flask/app.py", line 2292, in wsgi_app
    response = self.full_dispatch_request()
  File "/opt/wwd/lib64/python3.6/site-packages/flask/app.py", line 1815, in full_dispatch_request
    rv = self.handle_user_exception(e)
  File "/opt/wwd/lib64/python3.6/site-packages/flask/app.py", line 1718, in handle_user_exception
    reraise(exc_type, exc_value, tb)
  File "/opt/wwd/lib64/python3.6/site-packages/flask/_compat.py", line 35, in reraise
    raise value
  File "/opt/wwd/lib64/python3.6/site-packages/flask/app.py", line 1813, in full_dispatch_request
    rv = self.dispatch_request()
  File "/opt/wwd/lib64/python3.6/site-packages/flask/app.py", line 1799, in dispatch_request
    return self.view_functions[rule.endpoint](**req.view_args)
  File "./Routes.py", line 138, in all_orgs
    data = db.get_all_programs_json()
  File "./queries.py", line 552, in get_all_programs_json
    return [pgrm.json_details() for pgrm in self.get_all_programs()]
  File "./queries.py", line 548, in get_all_programs
    return [self.get_program(name) for name in self.get_program_names()]
  File "./queries.py", line 548, in <listcomp>
    return [self.get_program(name) for name in self.get_program_names()]
  File "./queries.py", line 731, in get_program
    pgrm.contacts = self.get_contacts(org, req_id)
  File "./queries.py", line 755, in get_contacts
    for org, school, prefix, first_name, last_name, suffix, title, email1, dept, dept_url, office, phone in results]
  File "./queries.py", line 755, in <listcomp>
    for org, school, prefix, first_name, last_name, suffix, title, email1, dept, dept_url, office, phone in results]
  File "./queries.py", line 251, in __init__
    self.office = office.strip()
AttributeError: 'NoneType' object has no attribute 'strip'
2018-10-19 18:27:56,578 - flask.app - ERROR - Exception on /all [GET]
Traceback (most recent call last):
  File "/opt/wwd/lib64/python3.6/site-packages/flask/app.py", line 2292, in wsgi_app
    response = self.full_dispatch_request()
  File "/opt/wwd/lib64/python3.6/site-packages/flask/app.py", line 1815, in full_dispatch_request
    rv = self.handle_user_exception(e)
  File "/opt/wwd/lib64/python3.6/site-packages/flask/app.py", line 1718, in handle_user_exception
    reraise(exc_type, exc_value, tb)
  File "/opt/wwd/lib64/python3.6/site-packages/flask/_compat.py", line 35, in reraise
    raise value
  File "/opt/wwd/lib64/python3.6/site-packages/flask/app.py", line 1813, in full_dispatch_request
    rv = self.dispatch_request()
  File "/opt/wwd/lib64/python3.6/site-packages/flask/app.py", line 1799, in dispatch_request
    return self.view_functions[rule.endpoint](**req.view_args)
  File "./Routes.py", line 138, in all_orgs
    data = db.get_all_programs_json()
  File "./queries.py", line 552, in get_all_programs_json
    return [pgrm.json_details() for pgrm in self.get_all_programs()]
  File "./queries.py", line 548, in get_all_programs
    return [self.get_program(name) for name in self.get_program_names()]
  File "./queries.py", line 548, in <listcomp>
    return [self.get_program(name) for name in self.get_program_names()]
  File "./queries.py", line 731, in get_program
    pgrm.contacts = self.get_contacts(org, req_id)
  File "./queries.py", line 755, in get_contacts
    for org, school, prefix, first_name, last_name, suffix, title, email1, dept, dept_url, office, phone in results]
  File "./queries.py", line 755, in <listcomp>
    for org, school, prefix, first_name, last_name, suffix, title, email1, dept, dept_url, office, phone in results]
  File "./queries.py", line 251, in __init__
    self.office = office.strip()
AttributeError: 'NoneType' object has no attribute 'strip'
2018-10-19 18:29:03,114 - flask.app - ERROR - Exception on /all [GET]
Traceback (most recent call last):
  File "/opt/wwd/lib64/python3.6/site-packages/flask/app.py", line 2292, in wsgi_app
    response = self.full_dispatch_request()
  File "/opt/wwd/lib64/python3.6/site-packages/flask/app.py", line 1815, in full_dispatch_request
    rv = self.handle_user_exception(e)
  File "/opt/wwd/lib64/python3.6/site-packages/flask/app.py", line 1718, in handle_user_exception
    reraise(exc_type, exc_value, tb)
  File "/opt/wwd/lib64/python3.6/site-packages/flask/_compat.py", line 35, in reraise
    raise value
  File "/opt/wwd/lib64/python3.6/site-packages/flask/app.py", line 1813, in full_dispatch_request
    rv = self.dispatch_request()
  File "/opt/wwd/lib64/python3.6/site-packages/flask/app.py", line 1799, in dispatch_request
    return self.view_functions[rule.endpoint](**req.view_args)
  File "./Routes.py", line 138, in all_orgs
    data = db.get_all_programs_json()
  File "./queries.py", line 552, in get_all_programs_json
    return [pgrm.json_details() for pgrm in self.get_all_programs()]
  File "./queries.py", line 548, in get_all_programs
    return [self.get_program(name) for name in self.get_program_names()]
  File "./queries.py", line 548, in <listcomp>
    return [self.get_program(name) for name in self.get_program_names()]
  File "./queries.py", line 731, in get_program
    pgrm.contacts = self.get_contacts(org, req_id)
  File "./queries.py", line 755, in get_contacts
    for org, school, prefix, first_name, last_name, suffix, title, email1, dept, dept_url, office, phone in results]
  File "./queries.py", line 755, in <listcomp>
    for org, school, prefix, first_name, last_name, suffix, title, email1, dept, dept_url, office, phone in results]
  File "./queries.py", line 251, in __init__
    self.office = office.strip()
AttributeError: 'NoneType' object has no attribute 'strip'
2018-10-19 18:29:11,918 - flask.app - ERROR - Exception on /all [GET]
Traceback (most recent call last):
  File "/opt/wwd/lib64/python3.6/site-packages/flask/app.py", line 2292, in wsgi_app
    response = self.full_dispatch_request()
  File "/opt/wwd/lib64/python3.6/site-packages/flask/app.py", line 1815, in full_dispatch_request
    rv = self.handle_user_exception(e)
  File "/opt/wwd/lib64/python3.6/site-packages/flask/app.py", line 1718, in handle_user_exception
    reraise(exc_type, exc_value, tb)
  File "/opt/wwd/lib64/python3.6/site-packages/flask/_compat.py", line 35, in reraise
    raise value
  File "/opt/wwd/lib64/python3.6/site-packages/flask/app.py", line 1813, in full_dispatch_request
    rv = self.dispatch_request()
  File "/opt/wwd/lib64/python3.6/site-packages/flask/app.py", line 1799, in dispatch_request
    return self.view_functions[rule.endpoint](**req.view_args)
  File "./Routes.py", line 138, in all_orgs
    data = db.get_all_programs_json()
  File "./queries.py", line 552, in get_all_programs_json
    return [pgrm.json_details() for pgrm in self.get_all_programs()]
  File "./queries.py", line 548, in get_all_programs
    return [self.get_program(name) for name in self.get_program_names()]
  File "./queries.py", line 548, in <listcomp>
    return [self.get_program(name) for name in self.get_program_names()]
  File "./queries.py", line 731, in get_program
    pgrm.contacts = self.get_contacts(org, req_id)
  File "./queries.py", line 755, in get_contacts
    for org, school, prefix, first_name, last_name, suffix, title, email1, dept, dept_url, office, phone in results]
  File "./queries.py", line 755, in <listcomp>
    for org, school, prefix, first_name, last_name, suffix, title, email1, dept, dept_url, office, phone in results]
  File "./queries.py", line 251, in __init__
    self.office = office.strip()
AttributeError: 'NoneType' object has no attribute 'strip'
2018-10-19 18:29:32,162 - flask.app - ERROR - Exception on /all [GET]
Traceback (most recent call last):
  File "/opt/wwd/lib64/python3.6/site-packages/flask/app.py", line 2292, in wsgi_app
    response = self.full_dispatch_request()
  File "/opt/wwd/lib64/python3.6/site-packages/flask/app.py", line 1815, in full_dispatch_request
    rv = self.handle_user_exception(e)
  File "/opt/wwd/lib64/python3.6/site-packages/flask/app.py", line 1718, in handle_user_exception
    reraise(exc_type, exc_value, tb)
  File "/opt/wwd/lib64/python3.6/site-packages/flask/_compat.py", line 35, in reraise
    raise value
  File "/opt/wwd/lib64/python3.6/site-packages/flask/app.py", line 1813, in full_dispatch_request
    rv = self.dispatch_request()
  File "/opt/wwd/lib64/python3.6/site-packages/flask/app.py", line 1799, in dispatch_request
    return self.view_functions[rule.endpoint](**req.view_args)
  File "./Routes.py", line 138, in all_orgs
    data = db.get_all_programs_json()
  File "./queries.py", line 552, in get_all_programs_json
    return [pgrm.json_details() for pgrm in self.get_all_programs()]
  File "./queries.py", line 548, in get_all_programs
    return [self.get_program(name) for name in self.get_program_names()]
  File "./queries.py", line 548, in <listcomp>
    return [self.get_program(name) for name in self.get_program_names()]
  File "./queries.py", line 731, in get_program
    pgrm.contacts = self.get_contacts(org, req_id)
  File "./queries.py", line 755, in get_contacts
    for org, school, prefix, first_name, last_name, suffix, title, email1, dept, dept_url, office, phone in results]
  File "./queries.py", line 755, in <listcomp>
    for org, school, prefix, first_name, last_name, suffix, title, email1, dept, dept_url, office, phone in results]
  File "./queries.py", line 251, in __init__
    self.office = office.strip()
AttributeError: 'NoneType' object has no attribute 'strip'
2018-10-19 18:29:37,694 - flask.app - ERROR - Exception on /all [GET]
Traceback (most recent call last):
  File "/opt/wwd/lib64/python3.6/site-packages/flask/app.py", line 2292, in wsgi_app
    response = self.full_dispatch_request()
  File "/opt/wwd/lib64/python3.6/site-packages/flask/app.py", line 1815, in full_dispatch_request
    rv = self.handle_user_exception(e)
  File "/opt/wwd/lib64/python3.6/site-packages/flask/app.py", line 1718, in handle_user_exception
    reraise(exc_type, exc_value, tb)
  File "/opt/wwd/lib64/python3.6/site-packages/flask/_compat.py", line 35, in reraise
    raise value
  File "/opt/wwd/lib64/python3.6/site-packages/flask/app.py", line 1813, in full_dispatch_request
    rv = self.dispatch_request()
  File "/opt/wwd/lib64/python3.6/site-packages/flask/app.py", line 1799, in dispatch_request
    return self.view_functions[rule.endpoint](**req.view_args)
  File "./Routes.py", line 138, in all_orgs
    data = db.get_all_programs_json()
  File "./queries.py", line 552, in get_all_programs_json
    return [pgrm.json_details() for pgrm in self.get_all_programs()]
  File "./queries.py", line 548, in get_all_programs
    return [self.get_program(name) for name in self.get_program_names()]
  File "./queries.py", line 548, in <listcomp>
    return [self.get_program(name) for name in self.get_program_names()]
  File "./queries.py", line 731, in get_program
    pgrm.contacts = self.get_contacts(org, req_id)
  File "./queries.py", line 755, in get_contacts
    for org, school, prefix, first_name, last_name, suffix, title, email1, dept, dept_url, office, phone in results]
  File "./queries.py", line 755, in <listcomp>
    for org, school, prefix, first_name, last_name, suffix, title, email1, dept, dept_url, office, phone in results]
  File "./queries.py", line 251, in __init__
    self.office = office.strip()
AttributeError: 'NoneType' object has no attribute 'strip'
2018-10-19 18:29:54,557 - flask.app - ERROR - Exception on /search_results [POST]
Traceback (most recent call last):
  File "/opt/wwd/lib64/python3.6/site-packages/flask/app.py", line 2292, in wsgi_app
    response = self.full_dispatch_request()
  File "/opt/wwd/lib64/python3.6/site-packages/flask/app.py", line 1815, in full_dispatch_request
    rv = self.handle_user_exception(e)
  File "/opt/wwd/lib64/python3.6/site-packages/flask/app.py", line 1718, in handle_user_exception
    reraise(exc_type, exc_value, tb)
  File "/opt/wwd/lib64/python3.6/site-packages/flask/_compat.py", line 35, in reraise
    raise value
  File "/opt/wwd/lib64/python3.6/site-packages/flask/app.py", line 1813, in full_dispatch_request
    rv = self.dispatch_request()
  File "/opt/wwd/lib64/python3.6/site-packages/flask/app.py", line 1799, in dispatch_request
    return self.view_functions[rule.endpoint](**req.view_args)
  File "./Routes.py", line 235, in advanced_search_results
    criteria, data = db.advanced_search(org, discipline, level, continent, country, state)
  File "./queries.py", line 707, in advanced_search
    return criteria, [self.get_program(result[0]).json_details() for result in self.run_query(query, args)]
  File "./queries.py", line 707, in <listcomp>
    return criteria, [self.get_program(result[0]).json_details() for result in self.run_query(query, args)]
  File "./queries.py", line 731, in get_program
    pgrm.contacts = self.get_contacts(org, req_id)
  File "./queries.py", line 755, in get_contacts
    for org, school, prefix, first_name, last_name, suffix, title, email1, dept, dept_url, office, phone in results]
  File "./queries.py", line 755, in <listcomp>
    for org, school, prefix, first_name, last_name, suffix, title, email1, dept, dept_url, office, phone in results]
  File "./queries.py", line 251, in __init__
    self.office = office.strip()
AttributeError: 'NoneType' object has no attribute 'strip'
2018-10-19 18:30:08,727 - flask.app - ERROR - Exception on /search_results [POST]
Traceback (most recent call last):
  File "/opt/wwd/lib64/python3.6/site-packages/flask/app.py", line 2292, in wsgi_app
    response = self.full_dispatch_request()
  File "/opt/wwd/lib64/python3.6/site-packages/flask/app.py", line 1815, in full_dispatch_request
    rv = self.handle_user_exception(e)
  File "/opt/wwd/lib64/python3.6/site-packages/flask/app.py", line 1718, in handle_user_exception
    reraise(exc_type, exc_value, tb)
  File "/opt/wwd/lib64/python3.6/site-packages/flask/_compat.py", line 35, in reraise
    raise value
  File "/opt/wwd/lib64/python3.6/site-packages/flask/app.py", line 1813, in full_dispatch_request
    rv = self.dispatch_request()
  File "/opt/wwd/lib64/python3.6/site-packages/flask/app.py", line 1799, in dispatch_request
    return self.view_functions[rule.endpoint](**req.view_args)
  File "./Routes.py", line 235, in advanced_search_results
    criteria, data = db.advanced_search(org, discipline, level, continent, country, state)
  File "./queries.py", line 707, in advanced_search
    return criteria, [self.get_program(result[0]).json_details() for result in self.run_query(query, args)]
  File "./queries.py", line 707, in <listcomp>
    return criteria, [self.get_program(result[0]).json_details() for result in self.run_query(query, args)]
  File "./queries.py", line 731, in get_program
    pgrm.contacts = self.get_contacts(org, req_id)
  File "./queries.py", line 755, in get_contacts
    for org, school, prefix, first_name, last_name, suffix, title, email1, dept, dept_url, office, phone in results]
  File "./queries.py", line 755, in <listcomp>
    for org, school, prefix, first_name, last_name, suffix, title, email1, dept, dept_url, office, phone in results]
  File "./queries.py", line 251, in __init__
    self.office = office.strip()
AttributeError: 'NoneType' object has no attribute 'strip'
2018-10-19 19:07:16,746 - flask.app - ERROR - 'NoneType' object has no attribute 'strip'
2018-10-19 19:07:33,515 - flask.app - ERROR - 'NoneType' object has no attribute 'strip'
2018-10-19 19:09:23,345 - flask.app - ERROR - 'NoneType' object has no attribute 'strip'
2018-10-23 20:15:03,915 - flask.app - ERROR - Exception on /admin/login [GET]
Traceback (most recent call last):
  File "/opt/wwd/lib64/python3.6/site-packages/flask/app.py", line 2292, in wsgi_app
    response = self.full_dispatch_request()
  File "/opt/wwd/lib64/python3.6/site-packages/flask/app.py", line 1815, in full_dispatch_request
    rv = self.handle_user_exception(e)
  File "/opt/wwd/lib64/python3.6/site-packages/flask/app.py", line 1718, in handle_user_exception
    reraise(exc_type, exc_value, tb)
  File "/opt/wwd/lib64/python3.6/site-packages/flask/_compat.py", line 35, in reraise
    raise value
  File "/opt/wwd/lib64/python3.6/site-packages/flask/app.py", line 1813, in full_dispatch_request
    rv = self.dispatch_request()
  File "/opt/wwd/lib64/python3.6/site-packages/flask/app.py", line 1799, in dispatch_request
    return self.view_functions[rule.endpoint](**req.view_args)
  File "./Routes.py", line 726, in admin_login
    return render_template('admin_login.html', create=False)
  File "/opt/wwd/lib64/python3.6/site-packages/flask/templating.py", line 135, in render_template
    context, ctx.app)
  File "/opt/wwd/lib64/python3.6/site-packages/flask/templating.py", line 117, in _render
    rv = template.render(context)
  File "/opt/wwd/lib64/python3.6/site-packages/jinja2/asyncsupport.py", line 76, in render
    return original_render(self, *args, **kwargs)
  File "/opt/wwd/lib64/python3.6/site-packages/jinja2/environment.py", line 1008, in render
    return self.environment.handle_exception(exc_info, True)
  File "/opt/wwd/lib64/python3.6/site-packages/jinja2/environment.py", line 780, in handle_exception
    reraise(exc_type, exc_value, tb)
  File "/opt/wwd/lib64/python3.6/site-packages/jinja2/_compat.py", line 37, in reraise
    raise value.with_traceback(tb)
  File "/opt/wwd/templates/admin_login.html", line 1, in top-level template code
    {%extends 'base.html'%}
  File "/opt/wwd/lib64/python3.6/site-packages/flask/templating.py", line 58, in get_source
    return self._get_source_fast(environment, template)
  File "/opt/wwd/lib64/python3.6/site-packages/flask/templating.py", line 86, in _get_source_fast
    raise TemplateNotFound(template)
jinja2.exceptions.TemplateNotFound: base.html
2018-10-25 02:09:15,352 - flask.app - ERROR - Exception on /scripts/setup.php [GET]
Traceback (most recent call last):
  File "/opt/wwd/lib64/python3.6/site-packages/flask/app.py", line 2292, in wsgi_app
    response = self.full_dispatch_request()
  File "/opt/wwd/lib64/python3.6/site-packages/flask/app.py", line 1815, in full_dispatch_request
    rv = self.handle_user_exception(e)
  File "/opt/wwd/lib64/python3.6/site-packages/flask/app.py", line 1718, in handle_user_exception
    reraise(exc_type, exc_value, tb)
  File "/opt/wwd/lib64/python3.6/site-packages/flask/_compat.py", line 35, in reraise
    raise value
  File "/opt/wwd/lib64/python3.6/site-packages/flask/app.py", line 1813, in full_dispatch_request
    rv = self.dispatch_request()
  File "/opt/wwd/lib64/python3.6/site-packages/flask/app.py", line 1799, in dispatch_request
    return self.view_functions[rule.endpoint](**req.view_args)
KeyError: 'scripts'
2018-10-28 04:47:25,964 - flask.app - ERROR - Exception on /scripts/setup.php [GET]
Traceback (most recent call last):
  File "/opt/wwd/lib64/python3.6/site-packages/flask/app.py", line 2292, in wsgi_app
    response = self.full_dispatch_request()
  File "/opt/wwd/lib64/python3.6/site-packages/flask/app.py", line 1815, in full_dispatch_request
    rv = self.handle_user_exception(e)
  File "/opt/wwd/lib64/python3.6/site-packages/flask/app.py", line 1718, in handle_user_exception
    reraise(exc_type, exc_value, tb)
  File "/opt/wwd/lib64/python3.6/site-packages/flask/_compat.py", line 35, in reraise
    raise value
  File "/opt/wwd/lib64/python3.6/site-packages/flask/app.py", line 1813, in full_dispatch_request
    rv = self.dispatch_request()
  File "/opt/wwd/lib64/python3.6/site-packages/flask/app.py", line 1799, in dispatch_request
    return self.view_functions[rule.endpoint](**req.view_args)
KeyError: 'scripts'
2018-11-13 15:17:06,689 - flask.app - ERROR - Exception on /scripts/cfformhistory.cfm [GET]
Traceback (most recent call last):
  File "/opt/wwd/lib64/python3.6/site-packages/flask/app.py", line 2292, in wsgi_app
    response = self.full_dispatch_request()
  File "/opt/wwd/lib64/python3.6/site-packages/flask/app.py", line 1815, in full_dispatch_request
    rv = self.handle_user_exception(e)
  File "/opt/wwd/lib64/python3.6/site-packages/flask/app.py", line 1718, in handle_user_exception
    reraise(exc_type, exc_value, tb)
  File "/opt/wwd/lib64/python3.6/site-packages/flask/_compat.py", line 35, in reraise
    raise value
  File "/opt/wwd/lib64/python3.6/site-packages/flask/app.py", line 1813, in full_dispatch_request
    rv = self.dispatch_request()
  File "/opt/wwd/lib64/python3.6/site-packages/flask/app.py", line 1799, in dispatch_request
    return self.view_functions[rule.endpoint](**req.view_args)
KeyError: 'scripts'
2018-11-13 15:17:08,272 - flask.app - ERROR - Exception on /scripts/ajax/ckeditor/plugins/filemanager/filemanager.cfm [GET]
Traceback (most recent call last):
  File "/opt/wwd/lib64/python3.6/site-packages/flask/app.py", line 2292, in wsgi_app
    response = self.full_dispatch_request()
  File "/opt/wwd/lib64/python3.6/site-packages/flask/app.py", line 1815, in full_dispatch_request
    rv = self.handle_user_exception(e)
  File "/opt/wwd/lib64/python3.6/site-packages/flask/app.py", line 1718, in handle_user_exception
    reraise(exc_type, exc_value, tb)
  File "/opt/wwd/lib64/python3.6/site-packages/flask/_compat.py", line 35, in reraise
    raise value
  File "/opt/wwd/lib64/python3.6/site-packages/flask/app.py", line 1813, in full_dispatch_request
    rv = self.dispatch_request()
  File "/opt/wwd/lib64/python3.6/site-packages/flask/app.py", line 1799, in dispatch_request
    return self.view_functions[rule.endpoint](**req.view_args)
KeyError: 'scripts'
2018-11-28 15:49:16,809 - flask.app - ERROR - Exception on /admin/login [GET]
Traceback (most recent call last):
  File "/opt/wwd/lib64/python3.6/site-packages/flask/app.py", line 2292, in wsgi_app
    response = self.full_dispatch_request()
  File "/opt/wwd/lib64/python3.6/site-packages/flask/app.py", line 1815, in full_dispatch_request
    rv = self.handle_user_exception(e)
  File "/opt/wwd/lib64/python3.6/site-packages/flask/app.py", line 1718, in handle_user_exception
    reraise(exc_type, exc_value, tb)
  File "/opt/wwd/lib64/python3.6/site-packages/flask/_compat.py", line 35, in reraise
    raise value
  File "/opt/wwd/lib64/python3.6/site-packages/flask/app.py", line 1813, in full_dispatch_request
    rv = self.dispatch_request()
  File "/opt/wwd/lib64/python3.6/site-packages/flask/app.py", line 1799, in dispatch_request
    return self.view_functions[rule.endpoint](**req.view_args)
  File "./Routes.py", line 711, in admin_login
    return render_template('admin_login.html', create=False)
  File "/opt/wwd/lib64/python3.6/site-packages/flask/templating.py", line 135, in render_template
    context, ctx.app)
  File "/opt/wwd/lib64/python3.6/site-packages/flask/templating.py", line 117, in _render
    rv = template.render(context)
  File "/opt/wwd/lib64/python3.6/site-packages/jinja2/asyncsupport.py", line 76, in render
    return original_render(self, *args, **kwargs)
  File "/opt/wwd/lib64/python3.6/site-packages/jinja2/environment.py", line 1008, in render
    return self.environment.handle_exception(exc_info, True)
  File "/opt/wwd/lib64/python3.6/site-packages/jinja2/environment.py", line 780, in handle_exception
    reraise(exc_type, exc_value, tb)
  File "/opt/wwd/lib64/python3.6/site-packages/jinja2/_compat.py", line 37, in reraise
    raise value.with_traceback(tb)
  File "/opt/wwd/templates/admin_login.html", line 1, in top-level template code
    {%extends 'base.html'%}
  File "/opt/wwd/lib64/python3.6/site-packages/flask/templating.py", line 58, in get_source
    return self._get_source_fast(environment, template)
  File "/opt/wwd/lib64/python3.6/site-packages/flask/templating.py", line 86, in _get_source_fast
    raise TemplateNotFound(template)
jinja2.exceptions.TemplateNotFound: base.html
2018-11-28 15:49:39,475 - flask.app - ERROR - Exception on /admin/login [GET]
Traceback (most recent call last):
  File "/opt/wwd/lib64/python3.6/site-packages/flask/app.py", line 2292, in wsgi_app
    response = self.full_dispatch_request()
  File "/opt/wwd/lib64/python3.6/site-packages/flask/app.py", line 1815, in full_dispatch_request
    rv = self.handle_user_exception(e)
  File "/opt/wwd/lib64/python3.6/site-packages/flask/app.py", line 1718, in handle_user_exception
    reraise(exc_type, exc_value, tb)
  File "/opt/wwd/lib64/python3.6/site-packages/flask/_compat.py", line 35, in reraise
    raise value
  File "/opt/wwd/lib64/python3.6/site-packages/flask/app.py", line 1813, in full_dispatch_request
    rv = self.dispatch_request()
  File "/opt/wwd/lib64/python3.6/site-packages/flask/app.py", line 1799, in dispatch_request
    return self.view_functions[rule.endpoint](**req.view_args)
  File "./Routes.py", line 711, in admin_login
    return render_template('admin_login.html', create=False)
  File "/opt/wwd/lib64/python3.6/site-packages/flask/templating.py", line 135, in render_template
    context, ctx.app)
  File "/opt/wwd/lib64/python3.6/site-packages/flask/templating.py", line 117, in _render
    rv = template.render(context)
  File "/opt/wwd/lib64/python3.6/site-packages/jinja2/asyncsupport.py", line 76, in render
    return original_render(self, *args, **kwargs)
  File "/opt/wwd/lib64/python3.6/site-packages/jinja2/environment.py", line 1008, in render
    return self.environment.handle_exception(exc_info, True)
  File "/opt/wwd/lib64/python3.6/site-packages/jinja2/environment.py", line 780, in handle_exception
    reraise(exc_type, exc_value, tb)
  File "/opt/wwd/lib64/python3.6/site-packages/jinja2/_compat.py", line 37, in reraise
    raise value.with_traceback(tb)
  File "/opt/wwd/templates/admin_login.html", line 1, in top-level template code
    {%extends 'base.html'%}
  File "/opt/wwd/lib64/python3.6/site-packages/flask/templating.py", line 58, in get_source
    return self._get_source_fast(environment, template)
  File "/opt/wwd/lib64/python3.6/site-packages/flask/templating.py", line 86, in _get_source_fast
    raise TemplateNotFound(template)
jinja2.exceptions.TemplateNotFound: base.html
2018-11-29 03:02:40,780 - flask.app - ERROR - Exception on /scripts/setup.php [GET]
Traceback (most recent call last):
  File "/opt/wwd/lib64/python3.6/site-packages/flask/app.py", line 2292, in wsgi_app
    response = self.full_dispatch_request()
  File "/opt/wwd/lib64/python3.6/site-packages/flask/app.py", line 1815, in full_dispatch_request
    rv = self.handle_user_exception(e)
  File "/opt/wwd/lib64/python3.6/site-packages/flask/app.py", line 1718, in handle_user_exception
    reraise(exc_type, exc_value, tb)
  File "/opt/wwd/lib64/python3.6/site-packages/flask/_compat.py", line 35, in reraise
    raise value
  File "/opt/wwd/lib64/python3.6/site-packages/flask/app.py", line 1813, in full_dispatch_request
    rv = self.dispatch_request()
  File "/opt/wwd/lib64/python3.6/site-packages/flask/app.py", line 1799, in dispatch_request
    return self.view_functions[rule.endpoint](**req.view_args)
KeyError: 'scripts'
2018-11-30 15:22:13,822 - flask.app - ERROR - Exception on /admin/login [GET]
Traceback (most recent call last):
  File "/opt/wwd/lib64/python3.6/site-packages/flask/app.py", line 2292, in wsgi_app
    response = self.full_dispatch_request()
  File "/opt/wwd/lib64/python3.6/site-packages/flask/app.py", line 1815, in full_dispatch_request
    rv = self.handle_user_exception(e)
  File "/opt/wwd/lib64/python3.6/site-packages/flask/app.py", line 1718, in handle_user_exception
    reraise(exc_type, exc_value, tb)
  File "/opt/wwd/lib64/python3.6/site-packages/flask/_compat.py", line 35, in reraise
    raise value
  File "/opt/wwd/lib64/python3.6/site-packages/flask/app.py", line 1813, in full_dispatch_request
    rv = self.dispatch_request()
  File "/opt/wwd/lib64/python3.6/site-packages/flask/app.py", line 1799, in dispatch_request
    return self.view_functions[rule.endpoint](**req.view_args)
  File "./Routes.py", line 711, in admin_login
    return render_template('admin_login.html', create=False)
  File "/opt/wwd/lib64/python3.6/site-packages/flask/templating.py", line 135, in render_template
    context, ctx.app)
  File "/opt/wwd/lib64/python3.6/site-packages/flask/templating.py", line 117, in _render
    rv = template.render(context)
  File "/opt/wwd/lib64/python3.6/site-packages/jinja2/asyncsupport.py", line 76, in render
    return original_render(self, *args, **kwargs)
  File "/opt/wwd/lib64/python3.6/site-packages/jinja2/environment.py", line 1008, in render
    return self.environment.handle_exception(exc_info, True)
  File "/opt/wwd/lib64/python3.6/site-packages/jinja2/environment.py", line 780, in handle_exception
    reraise(exc_type, exc_value, tb)
  File "/opt/wwd/lib64/python3.6/site-packages/jinja2/_compat.py", line 37, in reraise
    raise value.with_traceback(tb)
  File "/opt/wwd/templates/admin_login.html", line 1, in top-level template code
    {%extends 'base.html'%}
  File "/opt/wwd/lib64/python3.6/site-packages/flask/templating.py", line 58, in get_source
    return self._get_source_fast(environment, template)
  File "/opt/wwd/lib64/python3.6/site-packages/flask/templating.py", line 86, in _get_source_fast
    raise TemplateNotFound(template)
jinja2.exceptions.TemplateNotFound: base.html
2018-11-30 15:24:33,013 - flask.app - ERROR - Exception on /admin/login [GET]
Traceback (most recent call last):
  File "/opt/wwd/lib64/python3.6/site-packages/flask/app.py", line 2292, in wsgi_app
    response = self.full_dispatch_request()
  File "/opt/wwd/lib64/python3.6/site-packages/flask/app.py", line 1815, in full_dispatch_request
    rv = self.handle_user_exception(e)
  File "/opt/wwd/lib64/python3.6/site-packages/flask/app.py", line 1718, in handle_user_exception
    reraise(exc_type, exc_value, tb)
  File "/opt/wwd/lib64/python3.6/site-packages/flask/_compat.py", line 35, in reraise
    raise value
  File "/opt/wwd/lib64/python3.6/site-packages/flask/app.py", line 1813, in full_dispatch_request
    rv = self.dispatch_request()
  File "/opt/wwd/lib64/python3.6/site-packages/flask/app.py", line 1799, in dispatch_request
    return self.view_functions[rule.endpoint](**req.view_args)
  File "./Routes.py", line 711, in admin_login
    return render_template('admin_login.html', create=False)
  File "/opt/wwd/lib64/python3.6/site-packages/flask/templating.py", line 135, in render_template
    context, ctx.app)
  File "/opt/wwd/lib64/python3.6/site-packages/flask/templating.py", line 117, in _render
    rv = template.render(context)
  File "/opt/wwd/lib64/python3.6/site-packages/jinja2/asyncsupport.py", line 76, in render
    return original_render(self, *args, **kwargs)
  File "/opt/wwd/lib64/python3.6/site-packages/jinja2/environment.py", line 1008, in render
    return self.environment.handle_exception(exc_info, True)
  File "/opt/wwd/lib64/python3.6/site-packages/jinja2/environment.py", line 780, in handle_exception
    reraise(exc_type, exc_value, tb)
  File "/opt/wwd/lib64/python3.6/site-packages/jinja2/_compat.py", line 37, in reraise
    raise value.with_traceback(tb)
  File "/opt/wwd/templates/admin_login.html", line 1, in top-level template code
    {%extends 'base.html'%}
  File "/opt/wwd/lib64/python3.6/site-packages/flask/templating.py", line 58, in get_source
    return self._get_source_fast(environment, template)
  File "/opt/wwd/lib64/python3.6/site-packages/flask/templating.py", line 86, in _get_source_fast
    raise TemplateNotFound(template)
jinja2.exceptions.TemplateNotFound: base.html
2018-11-30 15:24:42,272 - flask.app - ERROR - Exception on /admin/login [GET]
Traceback (most recent call last):
  File "/opt/wwd/lib64/python3.6/site-packages/flask/app.py", line 2292, in wsgi_app
    response = self.full_dispatch_request()
  File "/opt/wwd/lib64/python3.6/site-packages/flask/app.py", line 1815, in full_dispatch_request
    rv = self.handle_user_exception(e)
  File "/opt/wwd/lib64/python3.6/site-packages/flask/app.py", line 1718, in handle_user_exception
    reraise(exc_type, exc_value, tb)
  File "/opt/wwd/lib64/python3.6/site-packages/flask/_compat.py", line 35, in reraise
    raise value
  File "/opt/wwd/lib64/python3.6/site-packages/flask/app.py", line 1813, in full_dispatch_request
    rv = self.dispatch_request()
  File "/opt/wwd/lib64/python3.6/site-packages/flask/app.py", line 1799, in dispatch_request
    return self.view_functions[rule.endpoint](**req.view_args)
  File "./Routes.py", line 711, in admin_login
    return render_template('admin_login.html', create=False)
  File "/opt/wwd/lib64/python3.6/site-packages/flask/templating.py", line 135, in render_template
    context, ctx.app)
  File "/opt/wwd/lib64/python3.6/site-packages/flask/templating.py", line 117, in _render
    rv = template.render(context)
  File "/opt/wwd/lib64/python3.6/site-packages/jinja2/asyncsupport.py", line 76, in render
    return original_render(self, *args, **kwargs)
  File "/opt/wwd/lib64/python3.6/site-packages/jinja2/environment.py", line 1008, in render
    return self.environment.handle_exception(exc_info, True)
  File "/opt/wwd/lib64/python3.6/site-packages/jinja2/environment.py", line 780, in handle_exception
    reraise(exc_type, exc_value, tb)
  File "/opt/wwd/lib64/python3.6/site-packages/jinja2/_compat.py", line 37, in reraise
    raise value.with_traceback(tb)
  File "/opt/wwd/templates/admin_login.html", line 1, in top-level template code
    {%extends 'base.html'%}
  File "/opt/wwd/lib64/python3.6/site-packages/flask/templating.py", line 58, in get_source
    return self._get_source_fast(environment, template)
  File "/opt/wwd/lib64/python3.6/site-packages/flask/templating.py", line 86, in _get_source_fast
    raise TemplateNotFound(template)
jinja2.exceptions.TemplateNotFound: base.html
2018-11-30 15:25:12,688 - flask.app - ERROR - Exception on /admin/login [GET]
Traceback (most recent call last):
  File "/opt/wwd/lib64/python3.6/site-packages/flask/app.py", line 2292, in wsgi_app
    response = self.full_dispatch_request()
  File "/opt/wwd/lib64/python3.6/site-packages/flask/app.py", line 1815, in full_dispatch_request
    rv = self.handle_user_exception(e)
  File "/opt/wwd/lib64/python3.6/site-packages/flask/app.py", line 1718, in handle_user_exception
    reraise(exc_type, exc_value, tb)
  File "/opt/wwd/lib64/python3.6/site-packages/flask/_compat.py", line 35, in reraise
    raise value
  File "/opt/wwd/lib64/python3.6/site-packages/flask/app.py", line 1813, in full_dispatch_request
    rv = self.dispatch_request()
  File "/opt/wwd/lib64/python3.6/site-packages/flask/app.py", line 1799, in dispatch_request
    return self.view_functions[rule.endpoint](**req.view_args)
  File "./Routes.py", line 711, in admin_login
    return render_template('admin_login.html', create=False)
  File "/opt/wwd/lib64/python3.6/site-packages/flask/templating.py", line 135, in render_template
    context, ctx.app)
  File "/opt/wwd/lib64/python3.6/site-packages/flask/templating.py", line 117, in _render
    rv = template.render(context)
  File "/opt/wwd/lib64/python3.6/site-packages/jinja2/asyncsupport.py", line 76, in render
    return original_render(self, *args, **kwargs)
  File "/opt/wwd/lib64/python3.6/site-packages/jinja2/environment.py", line 1008, in render
    return self.environment.handle_exception(exc_info, True)
  File "/opt/wwd/lib64/python3.6/site-packages/jinja2/environment.py", line 780, in handle_exception
    reraise(exc_type, exc_value, tb)
  File "/opt/wwd/lib64/python3.6/site-packages/jinja2/_compat.py", line 37, in reraise
    raise value.with_traceback(tb)
  File "/opt/wwd/templates/admin_login.html", line 1, in top-level template code
    {%extends 'base.html'%}
  File "/opt/wwd/lib64/python3.6/site-packages/flask/templating.py", line 58, in get_source
    return self._get_source_fast(environment, template)
  File "/opt/wwd/lib64/python3.6/site-packages/flask/templating.py", line 86, in _get_source_fast
    raise TemplateNotFound(template)
jinja2.exceptions.TemplateNotFound: base.html
2018-11-30 15:49:45,259 - flask.app - ERROR - base.html
2018-11-30 15:54:40,966 - flask.app - ERROR - Alternative: Use connection.MySQLCursorPrepared
2018-11-30 16:05:15,738 - flask.app - ERROR - Alternative: Use connection.MySQLCursorPrepared
2018-11-30 16:20:14,379 - flask.app - ERROR - [Errno 2] No such file or directory: '/var/lib/nginx/Downloads/WWD_Contacts_Exports20181130162014.xlsx'
2018-12-07 04:59:54,237 - flask.app - ERROR - 'scripts'
2018-12-07 20:16:09,028 - flask.app - ERROR - 'current' is undefined
2018-12-07 20:26:04,297 - flask.app - ERROR - 'current' is undefined
2018-12-07 20:26:15,073 - flask.app - ERROR - 'current' is undefined
2018-12-07 20:31:50,385 - flask.app - ERROR - 'current' is undefined
2018-12-07 20:35:43,332 - flask.app - ERROR - 'str object' has no attribute 'logo'
2018-12-07 20:45:15,501 - flask.app - ERROR - 'dict' object has no attribute 'logo'
2018-12-07 21:57:32,681 - flask.app - ERROR - Exception on /add [GET]
Traceback (most recent call last):
  File "/opt/wwd/lib64/python3.6/site-packages/flask/app.py", line 2292, in wsgi_app
    response = self.full_dispatch_request()
  File "/opt/wwd/lib64/python3.6/site-packages/flask/app.py", line 1815, in full_dispatch_request
    rv = self.handle_user_exception(e)
  File "/opt/wwd/lib64/python3.6/site-packages/flask/app.py", line 1718, in handle_user_exception
    reraise(exc_type, exc_value, tb)
  File "/opt/wwd/lib64/python3.6/site-packages/flask/_compat.py", line 35, in reraise
    raise value
  File "/opt/wwd/lib64/python3.6/site-packages/flask/app.py", line 1813, in full_dispatch_request
    rv = self.dispatch_request()
  File "/opt/wwd/lib64/python3.6/site-packages/flask/app.py", line 1799, in dispatch_request
    return self.view_functions[rule.endpoint](**req.view_args)
  File "./Routes.py", line 503, in add
    disciplines=disciplines, user=user, email=email, context=context, req_id=req_id)
  File "/opt/wwd/lib64/python3.6/site-packages/flask/templating.py", line 135, in render_template
    context, ctx.app)
  File "/opt/wwd/lib64/python3.6/site-packages/flask/templating.py", line 117, in _render
    rv = template.render(context)
  File "/opt/wwd/lib64/python3.6/site-packages/jinja2/asyncsupport.py", line 76, in render
    return original_render(self, *args, **kwargs)
  File "/opt/wwd/lib64/python3.6/site-packages/jinja2/environment.py", line 1008, in render
    return self.environment.handle_exception(exc_info, True)
  File "/opt/wwd/lib64/python3.6/site-packages/jinja2/environment.py", line 780, in handle_exception
    reraise(exc_type, exc_value, tb)
  File "/opt/wwd/lib64/python3.6/site-packages/jinja2/_compat.py", line 37, in reraise
    raise value.with_traceback(tb)
  File "/opt/wwd/templates/edit_add.html", line 1, in top-level template code
    {%extends 'Base.html' %}
  File "/opt/wwd/templates/Base.html", line 92, in top-level template code
    {% block body %}
  File "/opt/wwd/templates/edit_add.html", line 407, in block "body"
    {{captcha()}} <br>
jinja2.exceptions.UndefinedError: 'captcha' is undefined
2018-12-07 21:57:42,243 - flask.app - ERROR - Exception on /add [GET]
Traceback (most recent call last):
  File "/opt/wwd/lib64/python3.6/site-packages/flask/app.py", line 2292, in wsgi_app
    response = self.full_dispatch_request()
  File "/opt/wwd/lib64/python3.6/site-packages/flask/app.py", line 1815, in full_dispatch_request
    rv = self.handle_user_exception(e)
  File "/opt/wwd/lib64/python3.6/site-packages/flask/app.py", line 1718, in handle_user_exception
    reraise(exc_type, exc_value, tb)
  File "/opt/wwd/lib64/python3.6/site-packages/flask/_compat.py", line 35, in reraise
    raise value
  File "/opt/wwd/lib64/python3.6/site-packages/flask/app.py", line 1813, in full_dispatch_request
    rv = self.dispatch_request()
  File "/opt/wwd/lib64/python3.6/site-packages/flask/app.py", line 1799, in dispatch_request
    return self.view_functions[rule.endpoint](**req.view_args)
  File "./Routes.py", line 503, in add
    disciplines=disciplines, user=user, email=email, context=context, req_id=req_id)
  File "/opt/wwd/lib64/python3.6/site-packages/flask/templating.py", line 135, in render_template
    context, ctx.app)
  File "/opt/wwd/lib64/python3.6/site-packages/flask/templating.py", line 117, in _render
    rv = template.render(context)
  File "/opt/wwd/lib64/python3.6/site-packages/jinja2/asyncsupport.py", line 76, in render
    return original_render(self, *args, **kwargs)
  File "/opt/wwd/lib64/python3.6/site-packages/jinja2/environment.py", line 1008, in render
    return self.environment.handle_exception(exc_info, True)
  File "/opt/wwd/lib64/python3.6/site-packages/jinja2/environment.py", line 780, in handle_exception
    reraise(exc_type, exc_value, tb)
  File "/opt/wwd/lib64/python3.6/site-packages/jinja2/_compat.py", line 37, in reraise
    raise value.with_traceback(tb)
  File "/opt/wwd/templates/edit_add.html", line 1, in top-level template code
    {%extends 'Base.html' %}
  File "/opt/wwd/templates/Base.html", line 92, in top-level template code
    {% block body %}
  File "/opt/wwd/templates/edit_add.html", line 407, in block "body"
    {{captcha()}} <br>
jinja2.exceptions.UndefinedError: 'captcha' is undefined
2018-12-07 22:19:50,170 - flask.app - ERROR - Exception on /add [GET]
Traceback (most recent call last):
  File "/opt/wwd/lib64/python3.6/site-packages/flask/app.py", line 2292, in wsgi_app
    response = self.full_dispatch_request()
  File "/opt/wwd/lib64/python3.6/site-packages/flask/app.py", line 1815, in full_dispatch_request
    rv = self.handle_user_exception(e)
  File "/opt/wwd/lib64/python3.6/site-packages/flask/app.py", line 1718, in handle_user_exception
    reraise(exc_type, exc_value, tb)
  File "/opt/wwd/lib64/python3.6/site-packages/flask/_compat.py", line 35, in reraise
    raise value
  File "/opt/wwd/lib64/python3.6/site-packages/flask/app.py", line 1813, in full_dispatch_request
    rv = self.dispatch_request()
  File "/opt/wwd/lib64/python3.6/site-packages/flask/app.py", line 1799, in dispatch_request
    return self.view_functions[rule.endpoint](**req.view_args)
  File "./Routes.py", line 503, in add
    disciplines=disciplines, user=user, email=email, context=context, req_id=req_id)
  File "/opt/wwd/lib64/python3.6/site-packages/flask/templating.py", line 135, in render_template
    context, ctx.app)
  File "/opt/wwd/lib64/python3.6/site-packages/flask/templating.py", line 117, in _render
    rv = template.render(context)
  File "/opt/wwd/lib64/python3.6/site-packages/jinja2/asyncsupport.py", line 76, in render
    return original_render(self, *args, **kwargs)
  File "/opt/wwd/lib64/python3.6/site-packages/jinja2/environment.py", line 1008, in render
    return self.environment.handle_exception(exc_info, True)
  File "/opt/wwd/lib64/python3.6/site-packages/jinja2/environment.py", line 780, in handle_exception
    reraise(exc_type, exc_value, tb)
  File "/opt/wwd/lib64/python3.6/site-packages/jinja2/_compat.py", line 37, in reraise
    raise value.with_traceback(tb)
  File "/opt/wwd/templates/edit_add.html", line 1, in top-level template code
    {%extends 'Base.html' %}
  File "/opt/wwd/templates/Base.html", line 92, in top-level template code
    {% block body %}
  File "/opt/wwd/templates/edit_add.html", line 407, in block "body"
    {{captcha()}} <br>
jinja2.exceptions.UndefinedError: 'captcha' is undefined
2018-12-11 15:49:19,291 - flask.app - ERROR - 'NoneType' object has no attribute 'json_details'
2018-12-11 15:49:51,389 - flask.app - ERROR - 'NoneType' object has no attribute 'json_details'
2018-12-11 16:20:05,864 - flask.app - ERROR - 'AnonymousUserMixin' object has no attribute 'role'
2018-12-11 16:25:11,953 - flask.app - ERROR - [Errno 110] Connection timed out
2018-12-11 16:25:12,302 - flask.app - ERROR - [Errno 110] Connection timed out
2018-12-11 17:03:29,862 - flask.app - ERROR - [Errno 110] Connection timed out
2018-12-14 15:06:37,887 - flask.app - ERROR - Program already exists for Stevens Institute of Technology
2018-12-14 15:15:30,114 - flask.app - ERROR - Program already exists for Stevens Institute of Technology
2019-01-03 08:57:05,319 - flask.app - ERROR - 'scripts'
2019-01-07 02:36:24,660 - flask.app - ERROR - 'scripts'
2019-01-09 05:15:04,409 - flask.app - ERROR - 'scripts'
2019-01-23 17:51:31,221 - flask.app - ERROR - [Errno 2] No such file or directory: '/var/lib/nginx/Downloads/WWD_Contacts_Exports20190123175131.xlsx'
2019-01-24 16:43:35,469 - flask.app - ERROR - [Errno 2] No such file or directory: '/var/lib/nginx/Downloads/WWD_Contacts_Exports20190124164335.xlsx'
2019-02-12 11:30:58,225 - flask.app - ERROR - 'scripts'
2019-03-01 05:52:19,959 - flask.app - ERROR - 'scripts'
